<sdf version='1.6'>
  <world name='default'>
    <model name='camera_recorder'>
      <static>1</static>
      <pose frame=''>-11.4727 -23.2814 77.9846 0 1.2978 1.56422</pose>
      <link name='cam_link'>
        <visual name='visual'>
          <geometry>
            <box>
              <size>0.1 0.1 0.1</size>
            </box>
          </geometry>
        </visual>
        <sensor name='my_camera' type='camera'>
          <camera name='__default__'>
            <save enabled='1'>
              <path>/home/kostas/experiments/simulation/circular_turn</path>
            </save>
            <horizontal_fov>1.047</horizontal_fov>
            <image>
              <width>1920</width>
              <height>1080</height>
            </image>
            <clip>
              <near>0.1</near>
              <far>100</far>
            </clip>
          </camera>
          <always_on>1</always_on>
          <update_rate>30</update_rate>
        </sensor>
        <self_collide>0</self_collide>
        <enable_wind>0</enable_wind>
        <kinematic>0</kinematic>
      </link>
    </model>
    <gui fullscreen='0'>
      <plugin name='keyboard' filename='libKeyboardGUIPlugin.so'/>
      <camera name='user_camera'>
        <pose frame=''>-11.4727 -23.2814 77.9846 0 1.2978 1.56422</pose>
        <view_controller>orbit</view_controller>
        <projection_type>perspective</projection_type>
      </camera>
    </gui>
    <light name='sun' type='directional'>
      <cast_shadows>1</cast_shadows>
      <pose frame=''>0 0 10 0 -0 0</pose>
      <diffuse>0.8 0.8 0.8 1</diffuse>
      <specular>0.2 0.2 0.2 1</specular>
      <attenuation>
        <range>1000</range>
        <constant>0.9</constant>
        <linear>0.01</linear>
        <quadratic>0.001</quadratic>
      </attenuation>
      <direction>-0.5 0.1 -0.9</direction>
    </light>
    <gravity>0 0 -9.8</gravity>
    <magnetic_field>6e-06 2.3e-05 -4.2e-05</magnetic_field>
    <atmosphere type='adiabatic'/>
    <physics name='default_physics' default='0' type='ode'>
      <max_step_size>0.001</max_step_size>
      <real_time_factor>1</real_time_factor>
      <real_time_update_rate>1000</real_time_update_rate>
    </physics>
    <scene>
      <ambient>0.4 0.4 0.4 1</ambient>
      <background>0.7 0.7 0.7 1</background>
      <sky/>
      <shadows>1</shadows>
    </scene>
    <audio>
      <device>default</device>
    </audio>
    <wind/>
    <spherical_coordinates>
      <surface_model>EARTH_WGS84</surface_model>
      <latitude_deg>0</latitude_deg>
      <longitude_deg>0</longitude_deg>
      <elevation>0</elevation>
      <heading_deg>0</heading_deg>
    </spherical_coordinates>
    <state world_name='default'>
      <sim_time>3805 734000000</sim_time>
      <real_time>138 622592371</real_time>
      <wall_time>1574331465 590992705</wall_time>
      <iterations>136838</iterations>
      <model name='camera_recorder'>
        <pose frame=''>-11.4727 -23.2814 77.9846 0 1.2978 1.56422</pose>
        <scale>1 1 1</scale>
        <link name='cam_link'>
          <pose frame=''>-11.4727 -23.2814 77.9846 0 1.2978 1.56422</pose>
          <velocity>0 0 0 0 -0 0</velocity>
          <acceleration>0 0 0 0 -0 0</acceleration>
          <wrench>0 0 0 0 -0 0</wrench>
        </link>
      </model>
      <model name='cloverleaf_interchange'>
        <pose frame=''>121.481 -0.881388 0 0 -0 0</pose>
        <scale>1 1 1</scale>
        <link name='link'>
          <pose frame=''>121.481 -0.881388 0 0 -0 0</pose>
          <velocity>0 0 0 0 -0 0</velocity>
          <acceleration>0 0 0 0 -0 0</acceleration>
          <wrench>0 0 0 0 -0 0</wrench>
        </link>
      </model>
      <model name='ego_prius'>
        <pose frame=''>-18.0848 -1.13083 0.006898 0.000115 0.000175 0.041556</pose>
        <scale>1 1 1</scale>
        <link name='base_link'>
          <pose frame=''>-18.0848 -1.13083 0.006898 0.000115 0.000175 0.041556</pose>
          <velocity>-0.042101 0.006241 -0.002766 0.005101 -0.013164 -0.06818</velocity>
          <acceleration>-6.7419 0.283499 -0.044653 0.034455 0.04026 -2.90079</acceleration>
          <wrench>-6.7419 0.283499 -0.044653 0 -0 0</wrench>
        </link>
        <link name='chassis'>
          <pose frame=''>-16.6361 -1.0706 0.007574 -1.8e-05 -0.000115 1.61156</pose>
          <velocity>-0.038021 -0.014611 -0.015167 0.004831 -0.006591 -0.016084</velocity>
          <acceleration>-0.01954 0.014201 -0.044175 -0.002529 0.064086 -2.18671</acceleration>
          <wrench>-26.7897 19.4689 -60.5637 0 -0 0</wrench>
        </link>
        <link name='fl_axle'>
          <pose frame=''>-15.2585 -0.246789 0.307961 0.000301 -0.000144 1.61082</pose>
          <velocity>-0.025464 -0.038387 -0.037025 0.171869 -0.029623 -0.085821</velocity>
          <acceleration>2.1669 -2.58788 -0.029861 1.68685 0.890348 -0.536876</acceleration>
          <wrench>2.1669 -2.58788 -0.029861 0 -0 0</wrench>
        </link>
        <link name='fr_axle'>
          <pose frame=''>-15.196 -1.77953 0.307618 0.007419 -0.000741 1.61508</pose>
          <velocity>-0.050068 -0.038107 -0.019583 0.120158 -0.114499 1.03088</velocity>
          <acceleration>0.236795 -1.27065 -0.034352 1.43022 0.903176 1.16367</acceleration>
          <wrench>0.236795 -1.27065 -0.034352 0 -0 0</wrench>
        </link>
        <link name='front_left_wheel'>
          <pose frame=''>-15.2585 -0.246789 0.3079 -1.62293 -0.000182 1.61082</pose>
          <velocity>-0.025556 -0.03834 -0.029261 0.124224 -0.048958 -0.085637</velocity>
          <acceleration>2.10811 -2.62353 -0.030456 -1.40194 0.562385 2.63104</acceleration>
          <wrench>23.1892 -28.8588 -0.335017 0 -0 0</wrench>
        </link>
        <link name='front_right_wheel'>
          <pose frame=''>-15.196 -1.77953 0.307594 1.09265 -0.000575 1.61508</pose>
          <velocity>-0.05037 -0.038125 -0.017208 0.123846 -0.534519 1.0308</velocity>
          <acceleration>-0.152275 -1.27179 -0.050688 2.56862 1.34301 -1.62494</acceleration>
          <wrench>-1.67502 -13.9897 -0.557563 0 -0 0</wrench>
        </link>
        <link name='rear_left_wheel'>
          <pose frame=''>-18.1172 -0.337395 0.307645 0.464231 -7.6e-05 1.61156</pose>
          <velocity>-0.019095 0.008694 -0.021866 0.012688 -0.060825 -0.016083</velocity>
          <acceleration>11.1128 5.6341 0.199543 0.14766 1.0622 -2.18524</acceleration>
          <wrench>122.24 61.9751 2.19497 0 -0 0</wrench>
        </link>
        <link name='rear_right_wheel'>
          <pose frame=''>-18.0525 -1.92208 0.307463 2.92323 -4.6e-05 1.61156</pose>
          <velocity>-0.053772 0.004753 -0.029184 -0.014868 -0.006612 -0.016076</velocity>
          <acceleration>-2.18672 -0.209478 0.135954 -0.760637 -0.005216 0.970056</acceleration>
          <wrench>-24.0539 -2.30426 1.49549 0 -0 0</wrench>
        </link>
        <link name='steering_wheel'>
          <pose frame=''>-16.0233 -0.68769 0.995868 -1.30212 -8.6e-05 1.61157</pose>
          <velocity>-0.038426 -0.029241 -0.009199 0.000314 -0.006832 -0.014832</velocity>
          <acceleration>0.810406 -1.33605 -0.052261 -0.520878 0.010412 -1.73888</acceleration>
          <wrench>0.810406 -1.33605 -0.052261 0 -0 0</wrench>
        </link>
      </model>
      <model name='prius_slow'>
        <pose frame=''>-28.22 0.62305 0.006869 -0.000135 -0.000183 -1.5598</pose>
        <scale>1 1 1</scale>
        <link name='base_link'>
          <pose frame=''>-28.22 0.62305 0.006869 -0.000135 -0.000183 -1.5598</pose>
          <velocity>0.004931 -0.000833 -0.002333 -0.015274 0.004062 -0.052438</velocity>
          <acceleration>0.770223 -0.509606 2.1e-05 -0.003394 -0.031904 -2.9097</acceleration>
          <wrench>0.770223 -0.509606 2.1e-05 0 -0 0</wrench>
        </link>
        <link name='chassis'>
          <pose frame=''>-28.2041 -0.826861 0.008094 -0.000382 0.000135 0.011045</pose>
          <velocity>-0.002432 -0.000685 -0.017245 -0.007604 0.004166 -0.000427</velocity>
          <acceleration>-0.015192 0.000531 -0.006205 0.009148 0.004099 -0.083689</acceleration>
          <wrench>-20.8279 0.72844 -8.50764 0 -0 0</wrench>
        </link>
        <link name='fl_axle'>
          <pose frame=''>-27.4226 -2.22881 0.30862 3.5e-05 0.0002 0.009994</pose>
          <velocity>-0.001576 0.001821 -0.017373 0.023805 -0.010628 -0.421115</velocity>
          <acceleration>0.240921 1.13118 0.131907 1.14016 1.45112 0.610683</acceleration>
          <wrench>0.240921 1.13118 0.131907 0 -0 0</wrench>
        </link>
        <link name='fr_axle'>
          <pose frame=''>-28.9565 -2.24452 0.309035 0.000337 4e-06 0.010627</pose>
          <velocity>-0.002121 0.002853 -0.042094 0.041035 0.023876 0.721578</velocity>
          <acceleration>-0.808879 2.73765 0.122435 -2.31268 -0.66425 -0.824474</acceleration>
          <wrench>-0.808879 2.73765 0.122435 0 -0 0</wrench>
        </link>
        <link name='front_left_wheel'>
          <pose frame=''>-27.4226 -2.22881 0.3086 1.43408 0.000183 0.009994</pose>
          <velocity>-0.001565 0.001976 -0.015682 -0.006486 -0.007166 -0.42108</velocity>
          <acceleration>0.240253 1.50614 0.114683 2.34958 1.16903 -2.50154</acceleration>
          <wrench>2.64279 16.5675 1.26152 0 -0 0</wrench>
        </link>
        <link name='front_right_wheel'>
          <pose frame=''>-28.9565 -2.24452 0.308968 -0.802181 3.8e-05 0.010627</pose>
          <velocity>-0.002121 0.003012 -0.033454 -0.009868 0.018512 0.721563</velocity>
          <acceleration>-0.83704 2.95034 0.099096 -0.591648 1.36875 2.27831</acceleration>
          <wrench>-9.20744 32.4537 1.09005 0 -0 0</wrench>
        </link>
        <link name='pose_link'>
          <pose frame=''>-28.2041 -0.826861 0.008095 -0.000135 -0.000382 -1.55976</pose>
          <velocity>-0.00243 -0.000672 -0.017258 -0.007581 0.004164 -0.000464</velocity>
          <acceleration>-0.017052 0.005747 -0.006138 0.009126 0.004024 -0.157754</acceleration>
          <wrench>-0.017052 0.005747 -0.006138 0 -0 0</wrench>
        </link>
        <link name='rear_left_wheel'>
          <pose frame=''>-27.4259 0.631294 0.307442 -2.64244 0.000175 0.010245</pose>
          <velocity>-0.000116 0.002519 -0.032597 -0.008179 -0.000445 -0.000425</velocity>
          <acceleration>0.080558 -0.042614 -0.00184 0.134492 0.256517 -0.083099</acceleration>
          <wrench>0.886138 -0.468754 -0.020236 0 -0 0</wrench>
        </link>
        <link name='rear_right_wheel'>
          <pose frame=''>-29.0118 0.615053 0.30765 3.03349 0.000147 0.010245</pose>
          <velocity>-0.000123 0.002148 -0.025073 -0.006993 -0.000361 -0.000427</velocity>
          <acceleration>0.07989 0.0408 0.007013 -0.130716 0.256335 -0.083239</acceleration>
          <wrench>0.878795 0.448797 0.077138 0 -0 0</wrench>
        </link>
        <link name='steering_wheel'>
          <pose frame=''>-27.8398 -1.45065 0.996529 -1.30248 0.000134 0.010245</pose>
          <velocity>0.001422 0.006711 -0.01393 -0.007642 0.000277 -0.001497</velocity>
          <acceleration>-0.064582 -0.0368 -0.013123 0.00745 0.117018 -0.041007</acceleration>
          <wrench>-0.064582 -0.0368 -0.013123 0 -0 0</wrench>
        </link>
      </model>
      <light name='sun'>
        <pose frame=''>0.5 0 1 0 -0 0</pose>
      </light>
    </state>
    <model name='cloverleaf_interchange'>
      <static>1</static>
      <link name='link'>
        <collision name='collision'>
          <geometry>
            <mesh>
              <uri>model://cloverleaf_interchange/meshes/cloverleaf.obj</uri>
              <scale>0.0254 0.0254 0.0254</scale>
            </mesh>
          </geometry>
          <max_contacts>10</max_contacts>
          <surface>
            <contact>
              <ode/>
            </contact>
            <bounce/>
            <friction>
              <torsional>
                <ode/>
              </torsional>
              <ode/>
            </friction>
          </surface>
        </collision>
        <visual name='visual'>
          <geometry>
            <mesh>
              <uri>model://cloverleaf_interchange/meshes/cloverleaf.obj</uri>
              <scale>0.0254 0.0254 0.0254</scale>
            </mesh>
          </geometry>
        </visual>
        <self_collide>0</self_collide>
        <enable_wind>0</enable_wind>
        <kinematic>0</kinematic>
      </link>
      <pose frame=''>-295.324 348.572 0 0 -0 0</pose>
    </model>
    <gui fullscreen='1'>
      <camera name='user_camera'>
        <pose frame=''>164.478 -122.879 113.552 0 0.517796 2.38416</pose>
        <view_controller>orbit</view_controller>
        <projection_type>perspective</projection_type>
      </camera>
    </gui>
    <model name='ego_prius'>
      <link name='base_link'>
        <pose frame=''>0 0 0 0 -0 0</pose>
        <inertial>
          <pose frame=''>0 0 0 0 -0 0</pose>
          <mass>1</mass>
          <inertia>
            <ixx>0.001</ixx>
            <ixy>0</ixy>
            <ixz>0</ixz>
            <iyy>0.001</iyy>
            <iyz>0</iyz>
            <izz>0.001</izz>
          </inertia>
        </inertial>
        <self_collide>0</self_collide>
        <enable_wind>0</enable_wind>
        <kinematic>0</kinematic>
      </link>
      <link name='chassis'>
        <pose frame=''>1.45 0 0 0 -0 1.57</pose>
        <inertial>
          <pose frame=''>-0 -0.002735 0.483209 0 -0 1.5708</pose>
          <mass>1371</mass>
          <inertia>
            <ixx>2591.3</ixx>
            <ixy>0.000184475</ixy>
            <ixz>-0.702035</ixz>
            <iyy>651.702</iyy>
            <iyz>2.57872e-06</iyz>
            <izz>2744.57</izz>
          </inertia>
        </inertial>
        <collision name='chassis_fixed_joint_lump__back_bumper_collision_8'>
          <pose frame=''>0 2.05445 0.57787 0 -0 0</pose>
          <geometry>
            <box>
              <size>1.78165 0.512093 0.581427</size>
            </box>
          </geometry>
          <max_contacts>10</max_contacts>
          <surface>
            <contact>
              <ode/>
            </contact>
            <bounce/>
            <friction>
              <torsional>
                <ode/>
              </torsional>
              <ode/>
            </friction>
          </surface>
        </collision>
        <visual name='chassis_visual'>
          <pose frame=''>0 0 0 0 -0 0</pose>
          <geometry>
            <mesh>
              <scale>0.01 0.01 0.01</scale>
              <uri>/home/kostas/datmo_ws/src/car_demo-master/prius_description/meshes/hybrid_body.obj</uri>
            </mesh>
          </geometry>
        </visual>
        <velocity_decay/>
        <sensor name='center_laser_sensor' type='ray'>
          <ray>
            <scan>
              <horizontal>
                <samples>720</samples>
                <resolution>1</resolution>
                <min_angle>-3.14</min_angle>
                <max_angle>3.14</max_angle>
              </horizontal>
              <vertical>
                <samples>1</samples>
                <min_angle>0</min_angle>
                <max_angle>0</max_angle>
              </vertical>
            </scan>
            <range>
              <min>0.2</min>
              <max>70</max>
              <resolution>0.01</resolution>
            </range>
          </ray>
          <plugin name='center_laser' filename='libgazebo_ros_laser.so'>
            <topicName>/scan</topicName>
            <frameName>center_laser_link</frameName>
            <robotNamespace>/</robotNamespace>
          </plugin>
          <always_on>1</always_on>
          <update_rate>12</update_rate>
          <visualize>0</visualize>
          <pose frame=''>0 0 0.9 0 0 -1.5707</pose>
        </sensor>
        <velocity_decay/>
        <self_collide>0</self_collide>
        <enable_wind>0</enable_wind>
        <kinematic>0</kinematic>
      </link>
      <joint name='base_link_connection' type='revolute'>
        <child>chassis</child>
        <parent>base_link</parent>
        <axis>
          <limit>
            <lower>0</lower>
            <upper>0</upper>
          </limit>
          <dynamics>
            <damping>0</damping>
            <friction>0</friction>
            <spring_reference>0</spring_reference>
            <spring_stiffness>0</spring_stiffness>
          </dynamics>
          <use_parent_model_frame>1</use_parent_model_frame>
          <xyz>0 0 1</xyz>
        </axis>
        <physics>
          <ode>
            <limit>
              <cfm>0</cfm>
              <erp>0.2</erp>
            </limit>
          </ode>
        </physics>
      </joint>
      <link name='fl_axle'>
        <pose frame=''>2.86061 0.765877 0.3 0 -0 1.57</pose>
        <inertial>
          <pose frame=''>0 0 0 0 -0 0</pose>
          <mass>1</mass>
          <inertia>
            <ixx>0.004</ixx>
            <ixy>0</ixy>
            <ixz>0</ixz>
            <iyy>0.004</iyy>
            <iyz>0</iyz>
            <izz>0.004</izz>
          </inertia>
        </inertial>
        <self_collide>0</self_collide>
        <enable_wind>0</enable_wind>
        <kinematic>0</kinematic>
      </link>
      <joint name='front_left_steer_joint' type='revolute'>
        <child>fl_axle</child>
        <parent>chassis</parent>
        <axis>
          <xyz>0 0 1</xyz>
          <limit>
            <lower>-1e+16</lower>
            <upper>1e+16</upper>
          </limit>
          <dynamics>
            <spring_reference>0</spring_reference>
            <spring_stiffness>0</spring_stiffness>
          </dynamics>
          <use_parent_model_frame>1</use_parent_model_frame>
        </axis>
      </joint>
      <link name='front_left_wheel'>
        <pose frame=''>2.86061 0.765877 0.3 0 -0 1.57</pose>
        <inertial>
          <pose frame=''>0 0 0 0 -0 0</pose>
          <mass>11</mass>
          <inertia>
            <ixx>0.586312</ixx>
            <ixy>0</ixy>
            <ixz>0</ixz>
            <iyy>0.335529</iyy>
            <iyz>0</iyz>
            <izz>0.335529</izz>
          </inertia>
        </inertial>
        <collision name='front_left_wheel_collision_collision'>
          <pose frame=''>0 0 0 0 -0 0</pose>
          <geometry>
            <sphere>
              <radius>0.31265</radius>
            </sphere>
          </geometry>
          <surface>
            <contact>
              <ode>
                <kp>1e+08</kp>
                <min_depth>0.005</min_depth>
              </ode>
            </contact>
            <friction>
              <ode>
                <mu>0.9</mu>
                <mu2>0.9</mu2>
              </ode>
              <torsional>
                <ode/>
              </torsional>
            </friction>
            <bounce/>
          </surface>
          <max_contacts>10</max_contacts>
        </collision>
        <visual name='front_left_wheel_visual'>
          <pose frame=''>0 0 0 0 -0 0</pose>
          <geometry>
            <mesh>
              <scale>0.01 0.01 0.01</scale>
              <uri>/home/kostas/datmo_ws/src/car_demo-master/prius_description/meshes/wheel.obj</uri>
            </mesh>
          </geometry>
          <material>
            <script>
              <uri>__default__</uri>
              <name>__default__</name>
            </script>
          </material>
        </visual>
        <gravity>1</gravity>
        <velocity_decay/>
        <self_collide>0</self_collide>
        <enable_wind>0</enable_wind>
        <kinematic>0</kinematic>
      </link>
      <joint name='front_left_wheel_joint' type='revolute'>
        <child>front_left_wheel</child>
        <parent>fl_axle</parent>
        <axis>
          <xyz>0.000796 1 0</xyz>
          <limit>
            <lower>-1e+16</lower>
            <upper>1e+16</upper>
          </limit>
          <dynamics>
            <spring_reference>0</spring_reference>
            <spring_stiffness>0</spring_stiffness>
          </dynamics>
          <use_parent_model_frame>1</use_parent_model_frame>
        </axis>
      </joint>
      <link name='fr_axle'>
        <pose frame=''>2.85939 -0.768123 0.3 0 -0 1.57</pose>
        <inertial>
          <pose frame=''>0 0 0 0 -0 0</pose>
          <mass>1</mass>
          <inertia>
            <ixx>0.004</ixx>
            <ixy>0</ixy>
            <ixz>0</ixz>
            <iyy>0.004</iyy>
            <iyz>0</iyz>
            <izz>0.004</izz>
          </inertia>
        </inertial>
        <self_collide>0</self_collide>
        <enable_wind>0</enable_wind>
        <kinematic>0</kinematic>
      </link>
      <joint name='front_right_steer_joint' type='revolute'>
        <child>fr_axle</child>
        <parent>chassis</parent>
        <axis>
          <xyz>0 0 1</xyz>
          <limit>
            <lower>-1e+16</lower>
            <upper>1e+16</upper>
          </limit>
          <dynamics>
            <spring_reference>0</spring_reference>
            <spring_stiffness>0</spring_stiffness>
          </dynamics>
          <use_parent_model_frame>1</use_parent_model_frame>
        </axis>
      </joint>
      <link name='front_right_wheel'>
        <pose frame=''>2.85939 -0.768123 0.3 0 -0 1.57</pose>
        <inertial>
          <pose frame=''>0 0 0 0 -0 0</pose>
          <mass>11</mass>
          <inertia>
            <ixx>0.586312</ixx>
            <ixy>0</ixy>
            <ixz>0</ixz>
            <iyy>0.335529</iyy>
            <iyz>0</iyz>
            <izz>0.335529</izz>
          </inertia>
        </inertial>
        <collision name='front_right_wheel_collision_collision'>
          <pose frame=''>0 0 0 0 -0 0</pose>
          <geometry>
            <sphere>
              <radius>0.31265</radius>
            </sphere>
          </geometry>
          <surface>
            <contact>
              <ode>
                <kp>1e+08</kp>
                <min_depth>0.005</min_depth>
              </ode>
            </contact>
            <friction>
              <ode>
                <mu>0.9</mu>
                <mu2>0.9</mu2>
              </ode>
              <torsional>
                <ode/>
              </torsional>
            </friction>
            <bounce/>
          </surface>
          <max_contacts>10</max_contacts>
        </collision>
        <visual name='front_right_wheel_visual'>
          <pose frame=''>0 0 0 0 -0 0</pose>
          <geometry>
            <mesh>
              <scale>0.01 0.01 0.01</scale>
              <uri>/home/kostas/datmo_ws/src/car_demo-master/prius_description/meshes/wheel.obj</uri>
            </mesh>
          </geometry>
          <material>
            <script>
              <uri>__default__</uri>
              <name>__default__</name>
            </script>
          </material>
        </visual>
        <gravity>1</gravity>
        <velocity_decay/>
        <self_collide>0</self_collide>
        <enable_wind>0</enable_wind>
        <kinematic>0</kinematic>
      </link>
      <joint name='front_right_wheel_joint' type='revolute'>
        <child>front_right_wheel</child>
        <parent>fr_axle</parent>
        <axis>
          <xyz>0.000796 1 0</xyz>
          <limit>
            <lower>-1e+16</lower>
            <upper>1e+16</upper>
          </limit>
          <dynamics>
            <spring_reference>0</spring_reference>
            <spring_stiffness>0</spring_stiffness>
          </dynamics>
          <use_parent_model_frame>1</use_parent_model_frame>
        </axis>
      </joint>
      <link name='rear_left_wheel'>
        <pose frame=''>0.000632 0.794154 0.3 0 -0 1.57</pose>
        <inertial>
          <pose frame=''>0 0 0 0 -0 0</pose>
          <mass>11</mass>
          <inertia>
            <ixx>0.586312</ixx>
            <ixy>0</ixy>
            <ixz>0</ixz>
            <iyy>0.335529</iyy>
            <iyz>0</iyz>
            <izz>0.335529</izz>
          </inertia>
        </inertial>
        <collision name='rear_left_wheel_collision_collision'>
          <pose frame=''>0 0 0 0 -0 0</pose>
          <geometry>
            <sphere>
              <radius>0.31265</radius>
            </sphere>
          </geometry>
          <surface>
            <contact>
              <ode>
                <kp>1e+08</kp>
                <min_depth>0.005</min_depth>
              </ode>
            </contact>
            <friction>
              <ode>
                <mu>0.9</mu>
                <mu2>0.9</mu2>
              </ode>
              <torsional>
                <ode/>
              </torsional>
            </friction>
            <bounce/>
          </surface>
          <max_contacts>10</max_contacts>
        </collision>
        <visual name='rear_left_wheel_visual'>
          <pose frame=''>0 0 0 0 -0 0</pose>
          <geometry>
            <mesh>
              <scale>0.01 0.01 0.01</scale>
              <uri>/home/kostas/datmo_ws/src/car_demo-master/prius_description/meshes/wheel.obj</uri>
            </mesh>
          </geometry>
          <material>
            <script>
              <uri>__default__</uri>
              <name>__default__</name>
            </script>
          </material>
        </visual>
        <gravity>1</gravity>
        <velocity_decay/>
        <self_collide>0</self_collide>
        <enable_wind>0</enable_wind>
        <kinematic>0</kinematic>
      </link>
      <joint name='rear_left_wheel_joint' type='revolute'>
        <child>rear_left_wheel</child>
        <parent>chassis</parent>
        <axis>
          <xyz>0.000796 1 0</xyz>
          <limit>
            <lower>-1e+16</lower>
            <upper>1e+16</upper>
          </limit>
          <dynamics>
            <spring_reference>0</spring_reference>
            <spring_stiffness>0</spring_stiffness>
          </dynamics>
          <use_parent_model_frame>1</use_parent_model_frame>
        </axis>
      </joint>
      <link name='rear_right_wheel'>
        <pose frame=''>-0.000631 -0.791845 0.3 0 -0 1.57</pose>
        <inertial>
          <pose frame=''>0 0 0 0 -0 0</pose>
          <mass>11</mass>
          <inertia>
            <ixx>0.586312</ixx>
            <ixy>0</ixy>
            <ixz>0</ixz>
            <iyy>0.335529</iyy>
            <iyz>0</iyz>
            <izz>0.335529</izz>
          </inertia>
        </inertial>
        <collision name='rear_right_wheel_collision_collision'>
          <pose frame=''>0 0 0 0 -0 0</pose>
          <geometry>
            <sphere>
              <radius>0.31265</radius>
            </sphere>
          </geometry>
          <surface>
            <contact>
              <ode>
                <kp>1e+08</kp>
                <min_depth>0.005</min_depth>
              </ode>
            </contact>
            <friction>
              <ode>
                <mu>0.9</mu>
                <mu2>0.9</mu2>
              </ode>
              <torsional>
                <ode/>
              </torsional>
            </friction>
            <bounce/>
          </surface>
          <max_contacts>10</max_contacts>
        </collision>
        <visual name='rear_right_wheel_visual'>
          <pose frame=''>0 0 0 0 -0 0</pose>
          <geometry>
            <mesh>
              <scale>0.01 0.01 0.01</scale>
              <uri>/home/kostas/datmo_ws/src/car_demo-master/prius_description/meshes/wheel.obj</uri>
            </mesh>
          </geometry>
          <material>
            <script>
              <uri>__default__</uri>
              <name>__default__</name>
            </script>
          </material>
        </visual>
        <gravity>1</gravity>
        <velocity_decay/>
        <self_collide>0</self_collide>
        <enable_wind>0</enable_wind>
        <kinematic>0</kinematic>
      </link>
      <joint name='rear_right_wheel_joint' type='revolute'>
        <child>rear_right_wheel</child>
        <parent>chassis</parent>
        <axis>
          <xyz>0.000796 1 0</xyz>
          <limit>
            <lower>-1e+16</lower>
            <upper>1e+16</upper>
          </limit>
          <dynamics>
            <spring_reference>0</spring_reference>
            <spring_stiffness>0</spring_stiffness>
          </dynamics>
          <use_parent_model_frame>1</use_parent_model_frame>
        </axis>
      </joint>
      <link name='steering_wheel'>
        <pose frame=''>2.07815 0.357234 0.988243 -1.3021 0 1.57</pose>
        <inertial>
          <pose frame=''>0 0 0 0 -0 0</pose>
          <mass>1</mass>
          <inertia>
            <ixx>0.145833</ixx>
            <ixy>0</ixy>
            <ixz>0</ixz>
            <iyy>0.145833</iyy>
            <iyz>0</iyz>
            <izz>0.125</izz>
          </inertia>
        </inertial>
        <visual name='steering_wheel_visual'>
          <pose frame=''>0 0 0 1.3021 -0 0</pose>
          <geometry>
            <mesh>
              <scale>0.01 0.01 0.01</scale>
              <uri>/home/kostas/datmo_ws/src/car_demo-master/prius_description/meshes/steering_wheel.obj</uri>
            </mesh>
          </geometry>
        </visual>
        <self_collide>0</self_collide>
        <enable_wind>0</enable_wind>
        <kinematic>0</kinematic>
      </link>
      <joint name='steering_joint' type='revolute'>
        <child>steering_wheel</child>
        <parent>chassis</parent>
        <axis>
          <xyz>-0.964118 0.000768 0.265474</xyz>
          <limit>
            <lower>-1e+16</lower>
            <upper>1e+16</upper>
          </limit>
          <dynamics>
            <spring_reference>0</spring_reference>
            <spring_stiffness>0</spring_stiffness>
          </dynamics>
          <use_parent_model_frame>1</use_parent_model_frame>
        </axis>
      </joint>
      <plugin name='pruis_hybrid_drive' filename='libActor.so'>
        <controlTopic>ego</controlTopic>
        <chassis>chassis</chassis>
        <front_left_wheel>front_left_wheel_joint</front_left_wheel>
        <front_right_wheel>front_right_wheel_joint</front_right_wheel>
        <front_left_wheel_steering>front_left_steer_joint</front_left_wheel_steering>
        <front_right_wheel_steering>front_right_steer_joint</front_right_wheel_steering>
        <back_left_wheel>rear_left_wheel_joint</back_left_wheel>
        <back_right_wheel>rear_right_wheel_joint</back_right_wheel>
        <steering_wheel>steering_joint</steering_wheel>
        <chassis_aero_force_gain>0.63045</chassis_aero_force_gain>
        <front_torque>859.4004393000001</front_torque>
        <back_torque>0</back_torque>
        <front_brake_torque>1031.28052716</front_brake_torque>
        <back_brake_torque>687.5203514400001</back_brake_torque>
        <max_speed>10</max_speed>
        <min_gas_flow>8.981854013171626e-05</min_gas_flow>
        <gas_efficiency>0.371</gas_efficiency>
        <battery_charge_watt_hours>291</battery_charge_watt_hours>
        <battery_discharge_watt_hours>214</battery_discharge_watt_hours>
        <max_steer>0.8458</max_steer>
        <flwheel_steering_p_gain>1e4</flwheel_steering_p_gain>
        <frwheel_steering_p_gain>1e4</frwheel_steering_p_gain>
        <flwheel_steering_i_gain>0</flwheel_steering_i_gain>
        <frwheel_steering_i_gain>0</frwheel_steering_i_gain>
        <flwheel_steering_d_gain>3e2</flwheel_steering_d_gain>
        <frwheel_steering_d_gain>3e2</frwheel_steering_d_gain>
        <robotNamespace>/</robotNamespace>
      </plugin>
      <plugin name='joint_state_publisher' filename='libgazebo_ros_joint_state_publisher.so'>
        <jointName>rear_right_wheel_joint, rear_left_wheel_joint, front_right_wheel_joint, front_left_wheel_joint, front_right_steer_joint, front_left_steer_joint, steering_joint</jointName>
        <updateRate>100.0</updateRate>
        <alwaysOn>1</alwaysOn>
        <robotNamespace>/</robotNamespace>
      </plugin>
      <static>0</static>
      <plugin name='p3d' filename='libgazebo_ros_p3d.so'>
        <bodyName>base_link</bodyName>
        <topicName>ego_pose</topicName>
        <frameName>map</frameName>
        <updateRate>100.0</updateRate>
        <robotNamespace>/</robotNamespace>
      </plugin>
      <pose frame=''>1 -2 0.5 0 -0 0</pose>
    </model>
    <model name='prius_slow'>
      <link name='base_link'>
        <pose frame=''>0 0 0 0 -0 0</pose>
        <inertial>
          <pose frame=''>0 0 0 0 -0 0</pose>
          <mass>1</mass>
          <inertia>
            <ixx>0.001</ixx>
            <ixy>0</ixy>
            <ixz>0</ixz>
            <iyy>0.001</iyy>
            <iyz>0</iyz>
            <izz>0.001</izz>
          </inertia>
        </inertial>
        <self_collide>0</self_collide>
        <enable_wind>0</enable_wind>
        <kinematic>0</kinematic>
      </link>
      <link name='pose_link'>
        <pose frame=''>1.45 0 0 0 -0 0</pose>
        <inertial>
          <pose frame=''>0 0 0 0 -0 0</pose>
          <mass>1</mass>
          <inertia>
            <ixx>0.001</ixx>
            <ixy>0</ixy>
            <ixz>0</ixz>
            <iyy>0.001</iyy>
            <iyz>0</iyz>
            <izz>0.001</izz>
          </inertia>
        </inertial>
        <self_collide>0</self_collide>
        <enable_wind>0</enable_wind>
        <kinematic>0</kinematic>
      </link>
      <link name='chassis'>
        <pose frame=''>1.45 0 0 0 -0 1.5708</pose>
        <inertial>
          <pose frame=''>-0 -0.002735 0.483209 0 -0 1.5708</pose>
          <mass>1371</mass>
          <inertia>
            <ixx>2591.3</ixx>
            <ixy>0.000184475</ixy>
            <ixz>-0.702035</ixz>
            <iyy>651.702</iyy>
            <iyz>2.57872e-06</iyz>
            <izz>2744.57</izz>
          </inertia>
        </inertial>
        <collision name='chassis_collision'>
          <pose frame=''>0 0.05 0.625 0 -0 0</pose>
          <geometry>
            <box>
              <size>1.7526 2.1 0.95</size>
            </box>
          </geometry>
          <max_contacts>10</max_contacts>
          <surface>
            <contact>
              <ode/>
            </contact>
            <bounce/>
            <friction>
              <torsional>
                <ode/>
              </torsional>
              <ode/>
            </friction>
          </surface>
        </collision>
        <collision name='chassis_fixed_joint_lump__front_bumper_collision_1'>
          <pose frame=''>0 -2 0.458488 0 -0 0</pose>
          <geometry>
            <box>
              <size>1.33728 0.48 0.566691</size>
            </box>
          </geometry>
          <max_contacts>10</max_contacts>
          <surface>
            <contact>
              <ode/>
            </contact>
            <bounce/>
            <friction>
              <torsional>
                <ode/>
              </torsional>
              <ode/>
            </friction>
          </surface>
        </collision>
        <collision name='chassis_fixed_joint_lump__hood_collision_2'>
          <pose frame=''>0 -1.90084 0.676305 0.341247 -0 0</pose>
          <geometry>
            <box>
              <size>1.59797 0.493107 0.265468</size>
            </box>
          </geometry>
          <max_contacts>10</max_contacts>
          <surface>
            <contact>
              <ode/>
            </contact>
            <bounce/>
            <friction>
              <torsional>
                <ode/>
              </torsional>
              <ode/>
            </friction>
          </surface>
        </collision>
        <collision name='chassis_fixed_joint_lump__windshield_collision_3'>
          <pose frame=''>0 -0.875105 1.03227 0.335476 -0 0</pose>
          <geometry>
            <box>
              <size>1.16838 1.65425 0.272347</size>
            </box>
          </geometry>
          <max_contacts>10</max_contacts>
          <surface>
            <contact>
              <ode/>
            </contact>
            <bounce/>
            <friction>
              <torsional>
                <ode/>
              </torsional>
              <ode/>
            </friction>
          </surface>
        </collision>
        <collision name='chassis_fixed_joint_lump__top_front_collision_4'>
          <pose frame=''>0 0.161236 1.38604 0.13503 -0 0</pose>
          <geometry>
            <box>
              <size>1.27915 0.625988 0.171868</size>
            </box>
          </geometry>
          <max_contacts>10</max_contacts>
          <surface>
            <contact>
              <ode/>
            </contact>
            <bounce/>
            <friction>
              <torsional>
                <ode/>
              </torsional>
              <ode/>
            </friction>
          </surface>
        </collision>
        <collision name='chassis_fixed_joint_lump__top_rear_collision_5'>
          <pose frame=''>0 0.817696 1.36007 -0.068997 0 0</pose>
          <geometry>
            <box>
              <size>1.28513 0.771189 0.226557</size>
            </box>
          </geometry>
          <max_contacts>10</max_contacts>
          <surface>
            <contact>
              <ode/>
            </contact>
            <bounce/>
            <friction>
              <torsional>
                <ode/>
              </torsional>
              <ode/>
            </friction>
          </surface>
        </collision>
        <collision name='chassis_fixed_joint_lump__rear_window_collision_6'>
          <pose frame=''>0 1.64053 1.17513 -0.262017 0 0</pose>
          <geometry>
            <box>
              <size>1.26785 1.11634 0.244286</size>
            </box>
          </geometry>
          <max_contacts>10</max_contacts>
          <surface>
            <contact>
              <ode/>
            </contact>
            <bounce/>
            <friction>
              <torsional>
                <ode/>
              </torsional>
              <ode/>
            </friction>
          </surface>
        </collision>
        <collision name='chassis_fixed_joint_lump__trunk_collision_7'>
          <pose frame=''>0 1.63706 0.88818 0 -0 0</pose>
          <geometry>
            <box>
              <size>1.78806 1.13899 0.482746</size>
            </box>
          </geometry>
          <max_contacts>10</max_contacts>
          <surface>
            <contact>
              <ode/>
            </contact>
            <bounce/>
            <friction>
              <torsional>
                <ode/>
              </torsional>
              <ode/>
            </friction>
          </surface>
        </collision>
        <collision name='chassis_fixed_joint_lump__back_bumper_collision_8'>
          <pose frame=''>0 2.05445 0.57787 0 -0 0</pose>
          <geometry>
            <box>
              <size>1.78165 0.512093 0.581427</size>
            </box>
          </geometry>
          <max_contacts>10</max_contacts>
          <surface>
            <contact>
              <ode/>
            </contact>
            <bounce/>
            <friction>
              <torsional>
                <ode/>
              </torsional>
              <ode/>
            </friction>
          </surface>
        </collision>
        <visual name='chassis_visual'>
          <pose frame=''>0 0 0 0 -0 0</pose>
          <geometry>
            <mesh>
              <scale>0.01 0.01 0.01</scale>
              <uri>/home/kostas/datmo_ws/src/car_demo-master/prius_description/meshes/hybrid_body.obj</uri>
            </mesh>
          </geometry>
        </visual>
        <velocity_decay/>
        <self_collide>0</self_collide>
        <enable_wind>0</enable_wind>
        <kinematic>0</kinematic>
      </link>
      <joint name='pose_link_connection' type='revolute'>
        <child>chassis</child>
        <parent>pose_link</parent>
        <axis>
          <limit>
            <lower>0</lower>
            <upper>0</upper>
          </limit>
          <dynamics>
            <damping>0</damping>
            <friction>0</friction>
            <spring_reference>0</spring_reference>
            <spring_stiffness>0</spring_stiffness>
          </dynamics>
          <use_parent_model_frame>1</use_parent_model_frame>
          <xyz>0 0 1</xyz>
        </axis>
        <physics>
          <ode>
            <limit>
              <cfm>0</cfm>
              <erp>0.2</erp>
            </limit>
          </ode>
        </physics>
      </joint>
      <joint name='base_link_connection' type='revolute'>
        <child>chassis</child>
        <parent>base_link</parent>
        <axis>
          <limit>
            <lower>0</lower>
            <upper>0</upper>
          </limit>
          <dynamics>
            <damping>0</damping>
            <friction>0</friction>
            <spring_reference>0</spring_reference>
            <spring_stiffness>0</spring_stiffness>
          </dynamics>
          <use_parent_model_frame>1</use_parent_model_frame>
          <xyz>0 0 1</xyz>
        </axis>
        <physics>
          <ode>
            <limit>
              <cfm>0</cfm>
              <erp>0.2</erp>
            </limit>
          </ode>
        </physics>
      </joint>
      <link name='fl_axle'>
        <pose frame=''>2.86061 0.765877 0.3 0 -0 1.57</pose>
        <inertial>
          <pose frame=''>0 0 0 0 -0 0</pose>
          <mass>1</mass>
          <inertia>
            <ixx>0.004</ixx>
            <ixy>0</ixy>
            <ixz>0</ixz>
            <iyy>0.004</iyy>
            <iyz>0</iyz>
            <izz>0.004</izz>
          </inertia>
        </inertial>
        <self_collide>0</self_collide>
        <enable_wind>0</enable_wind>
        <kinematic>0</kinematic>
      </link>
      <joint name='front_left_steer_joint' type='revolute'>
        <child>fl_axle</child>
        <parent>chassis</parent>
        <axis>
          <xyz>0 0 1</xyz>
          <limit>
            <lower>-1e+16</lower>
            <upper>1e+16</upper>
          </limit>
          <dynamics>
            <spring_reference>0</spring_reference>
            <spring_stiffness>0</spring_stiffness>
          </dynamics>
          <use_parent_model_frame>1</use_parent_model_frame>
        </axis>
      </joint>
      <link name='front_left_wheel'>
        <pose frame=''>2.86061 0.765877 0.3 0 -0 1.57</pose>
        <inertial>
          <pose frame=''>0 0 0 0 -0 0</pose>
          <mass>11</mass>
          <inertia>
            <ixx>0.586312</ixx>
            <ixy>0</ixy>
            <ixz>0</ixz>
            <iyy>0.335529</iyy>
            <iyz>0</iyz>
            <izz>0.335529</izz>
          </inertia>
        </inertial>
        <collision name='front_left_wheel_collision_collision'>
          <pose frame=''>0 0 0 0 -0 0</pose>
          <geometry>
            <sphere>
              <radius>0.31265</radius>
            </sphere>
          </geometry>
          <surface>
            <contact>
              <ode>
                <kp>1e+08</kp>
                <min_depth>0.005</min_depth>
              </ode>
            </contact>
            <friction>
              <ode>
                <mu>0.9</mu>
                <mu2>0.9</mu2>
              </ode>
              <torsional>
                <ode/>
              </torsional>
            </friction>
            <bounce/>
          </surface>
          <max_contacts>10</max_contacts>
        </collision>
        <visual name='front_left_wheel_visual'>
          <pose frame=''>0 0 0 0 -0 0</pose>
          <geometry>
            <mesh>
              <scale>0.01 0.01 0.01</scale>
              <uri>/home/kostas/datmo_ws/src/car_demo-master/prius_description/meshes/wheel.obj</uri>
            </mesh>
          </geometry>
          <material>
            <script>
              <uri>__default__</uri>
              <name>__default__</name>
            </script>
          </material>
        </visual>
        <gravity>1</gravity>
        <velocity_decay/>
        <self_collide>0</self_collide>
        <enable_wind>0</enable_wind>
        <kinematic>0</kinematic>
      </link>
      <joint name='front_left_wheel_joint' type='revolute'>
        <child>front_left_wheel</child>
        <parent>fl_axle</parent>
        <axis>
          <xyz>0.000796 1 0</xyz>
          <limit>
            <lower>-1e+16</lower>
            <upper>1e+16</upper>
          </limit>
          <dynamics>
            <spring_reference>0</spring_reference>
            <spring_stiffness>0</spring_stiffness>
          </dynamics>
          <use_parent_model_frame>1</use_parent_model_frame>
        </axis>
      </joint>
      <link name='fr_axle'>
        <pose frame=''>2.85939 -0.768123 0.3 0 -0 1.57</pose>
        <inertial>
          <pose frame=''>0 0 0 0 -0 0</pose>
          <mass>1</mass>
          <inertia>
            <ixx>0.004</ixx>
            <ixy>0</ixy>
            <ixz>0</ixz>
            <iyy>0.004</iyy>
            <iyz>0</iyz>
            <izz>0.004</izz>
          </inertia>
        </inertial>
        <self_collide>0</self_collide>
        <enable_wind>0</enable_wind>
        <kinematic>0</kinematic>
      </link>
      <joint name='front_right_steer_joint' type='revolute'>
        <child>fr_axle</child>
        <parent>chassis</parent>
        <axis>
          <xyz>0 0 1</xyz>
          <limit>
            <lower>-1e+16</lower>
            <upper>1e+16</upper>
          </limit>
          <dynamics>
            <spring_reference>0</spring_reference>
            <spring_stiffness>0</spring_stiffness>
          </dynamics>
          <use_parent_model_frame>1</use_parent_model_frame>
        </axis>
      </joint>
      <link name='front_right_wheel'>
        <pose frame=''>2.85939 -0.768123 0.3 0 -0 1.57</pose>
        <inertial>
          <pose frame=''>0 0 0 0 -0 0</pose>
          <mass>11</mass>
          <inertia>
            <ixx>0.586312</ixx>
            <ixy>0</ixy>
            <ixz>0</ixz>
            <iyy>0.335529</iyy>
            <iyz>0</iyz>
            <izz>0.335529</izz>
          </inertia>
        </inertial>
        <collision name='front_right_wheel_collision_collision'>
          <pose frame=''>0 0 0 0 -0 0</pose>
          <geometry>
            <sphere>
              <radius>0.31265</radius>
            </sphere>
          </geometry>
          <surface>
            <contact>
              <ode>
                <kp>1e+08</kp>
                <min_depth>0.005</min_depth>
              </ode>
            </contact>
            <friction>
              <ode>
                <mu>0.9</mu>
                <mu2>0.9</mu2>
              </ode>
              <torsional>
                <ode/>
              </torsional>
            </friction>
            <bounce/>
          </surface>
          <max_contacts>10</max_contacts>
        </collision>
        <visual name='front_right_wheel_visual'>
          <pose frame=''>0 0 0 0 -0 0</pose>
          <geometry>
            <mesh>
              <scale>0.01 0.01 0.01</scale>
              <uri>/home/kostas/datmo_ws/src/car_demo-master/prius_description/meshes/wheel.obj</uri>
            </mesh>
          </geometry>
          <material>
            <script>
              <uri>__default__</uri>
              <name>__default__</name>
            </script>
          </material>
        </visual>
        <gravity>1</gravity>
        <velocity_decay/>
        <self_collide>0</self_collide>
        <enable_wind>0</enable_wind>
        <kinematic>0</kinematic>
      </link>
      <joint name='front_right_wheel_joint' type='revolute'>
        <child>front_right_wheel</child>
        <parent>fr_axle</parent>
        <axis>
          <xyz>0.000796 1 0</xyz>
          <limit>
            <lower>-1e+16</lower>
            <upper>1e+16</upper>
          </limit>
          <dynamics>
            <spring_reference>0</spring_reference>
            <spring_stiffness>0</spring_stiffness>
          </dynamics>
          <use_parent_model_frame>1</use_parent_model_frame>
        </axis>
      </joint>
      <link name='rear_left_wheel'>
        <pose frame=''>0.000632 0.794154 0.3 0 -0 1.57</pose>
        <inertial>
          <pose frame=''>0 0 0 0 -0 0</pose>
          <mass>11</mass>
          <inertia>
            <ixx>0.586312</ixx>
            <ixy>0</ixy>
            <ixz>0</ixz>
            <iyy>0.335529</iyy>
            <iyz>0</iyz>
            <izz>0.335529</izz>
          </inertia>
        </inertial>
        <collision name='rear_left_wheel_collision_collision'>
          <pose frame=''>0 0 0 0 -0 0</pose>
          <geometry>
            <sphere>
              <radius>0.31265</radius>
            </sphere>
          </geometry>
          <surface>
            <contact>
              <ode>
                <kp>1e+08</kp>
                <min_depth>0.005</min_depth>
              </ode>
            </contact>
            <friction>
              <ode>
                <mu>0.9</mu>
                <mu2>0.9</mu2>
              </ode>
              <torsional>
                <ode/>
              </torsional>
            </friction>
            <bounce/>
          </surface>
          <max_contacts>10</max_contacts>
        </collision>
        <visual name='rear_left_wheel_visual'>
          <pose frame=''>0 0 0 0 -0 0</pose>
          <geometry>
            <mesh>
              <scale>0.01 0.01 0.01</scale>
              <uri>/home/kostas/datmo_ws/src/car_demo-master/prius_description/meshes/wheel.obj</uri>
            </mesh>
          </geometry>
          <material>
            <script>
              <uri>__default__</uri>
              <name>__default__</name>
            </script>
          </material>
        </visual>
        <gravity>1</gravity>
        <velocity_decay/>
        <self_collide>0</self_collide>
        <enable_wind>0</enable_wind>
        <kinematic>0</kinematic>
      </link>
      <joint name='rear_left_wheel_joint' type='revolute'>
        <child>rear_left_wheel</child>
        <parent>chassis</parent>
        <axis>
          <xyz>0.000796 1 0</xyz>
          <limit>
            <lower>-1e+16</lower>
            <upper>1e+16</upper>
          </limit>
          <dynamics>
            <spring_reference>0</spring_reference>
            <spring_stiffness>0</spring_stiffness>
          </dynamics>
          <use_parent_model_frame>1</use_parent_model_frame>
        </axis>
      </joint>
      <link name='rear_right_wheel'>
        <pose frame=''>-0.000631 -0.791845 0.3 0 -0 1.57</pose>
        <inertial>
          <pose frame=''>0 0 0 0 -0 0</pose>
          <mass>11</mass>
          <inertia>
            <ixx>0.586312</ixx>
            <ixy>0</ixy>
            <ixz>0</ixz>
            <iyy>0.335529</iyy>
            <iyz>0</iyz>
            <izz>0.335529</izz>
          </inertia>
        </inertial>
        <collision name='rear_right_wheel_collision_collision'>
          <pose frame=''>0 0 0 0 -0 0</pose>
          <geometry>
            <sphere>
              <radius>0.31265</radius>
            </sphere>
          </geometry>
          <surface>
            <contact>
              <ode>
                <kp>1e+08</kp>
                <min_depth>0.005</min_depth>
              </ode>
            </contact>
            <friction>
              <ode>
                <mu>0.9</mu>
                <mu2>0.9</mu2>
              </ode>
              <torsional>
                <ode/>
              </torsional>
            </friction>
            <bounce/>
          </surface>
          <max_contacts>10</max_contacts>
        </collision>
        <visual name='rear_right_wheel_visual'>
          <pose frame=''>0 0 0 0 -0 0</pose>
          <geometry>
            <mesh>
              <scale>0.01 0.01 0.01</scale>
              <uri>/home/kostas/datmo_ws/src/car_demo-master/prius_description/meshes/wheel.obj</uri>
            </mesh>
          </geometry>
          <material>
            <script>
              <uri>__default__</uri>
              <name>__default__</name>
            </script>
          </material>
        </visual>
        <gravity>1</gravity>
        <velocity_decay/>
        <self_collide>0</self_collide>
        <enable_wind>0</enable_wind>
        <kinematic>0</kinematic>
      </link>
      <joint name='rear_right_wheel_joint' type='revolute'>
        <child>rear_right_wheel</child>
        <parent>chassis</parent>
        <axis>
          <xyz>0.000796 1 0</xyz>
          <limit>
            <lower>-1e+16</lower>
            <upper>1e+16</upper>
          </limit>
          <dynamics>
            <spring_reference>0</spring_reference>
            <spring_stiffness>0</spring_stiffness>
          </dynamics>
          <use_parent_model_frame>1</use_parent_model_frame>
        </axis>
      </joint>
      <link name='steering_wheel'>
        <pose frame=''>2.07815 0.357234 0.988243 -1.3021 0 1.57</pose>
        <inertial>
          <pose frame=''>0 0 0 0 -0 0</pose>
          <mass>1</mass>
          <inertia>
            <ixx>0.145833</ixx>
            <ixy>0</ixy>
            <ixz>0</ixz>
            <iyy>0.145833</iyy>
            <iyz>0</iyz>
            <izz>0.125</izz>
          </inertia>
        </inertial>
        <visual name='steering_wheel_visual'>
          <pose frame=''>0 0 0 1.3021 -0 0</pose>
          <geometry>
            <mesh>
              <scale>0.01 0.01 0.01</scale>
              <uri>/home/kostas/datmo_ws/src/car_demo-master/prius_description/meshes/steering_wheel.obj</uri>
            </mesh>
          </geometry>
        </visual>
        <self_collide>0</self_collide>
        <enable_wind>0</enable_wind>
        <kinematic>0</kinematic>
      </link>
      <joint name='steering_joint' type='revolute'>
        <child>steering_wheel</child>
        <parent>chassis</parent>
        <axis>
          <xyz>-0.964118 0.000768 0.265474</xyz>
          <limit>
            <lower>-1e+16</lower>
            <upper>1e+16</upper>
          </limit>
          <dynamics>
            <spring_reference>0</spring_reference>
            <spring_stiffness>0</spring_stiffness>
          </dynamics>
          <use_parent_model_frame>1</use_parent_model_frame>
        </axis>
      </joint>
      <plugin name='actorhybrid_drive' filename='libActor.so'>
        <controlTopic>slow</controlTopic>
        <chassis>chassis</chassis>
        <front_left_wheel>front_left_wheel_joint</front_left_wheel>
        <front_right_wheel>front_right_wheel_joint</front_right_wheel>
        <front_left_wheel_steering>front_left_steer_joint</front_left_wheel_steering>
        <front_right_wheel_steering>front_right_steer_joint</front_right_wheel_steering>
        <back_left_wheel>rear_left_wheel_joint</back_left_wheel>
        <back_right_wheel>rear_right_wheel_joint</back_right_wheel>
        <steering_wheel>steering_joint</steering_wheel>
        <chassis_aero_force_gain>0.63045</chassis_aero_force_gain>
        <front_torque>700.4004393000001</front_torque>
        <back_torque>0</back_torque>
        <front_brake_torque>1031.28052716</front_brake_torque>
        <back_brake_torque>687.5203514400001</back_brake_torque>
        <max_speed>5</max_speed>
        <min_gas_flow>8.981854013171626e-05</min_gas_flow>
        <gas_efficiency>0.371</gas_efficiency>
        <battery_charge_watt_hours>291</battery_charge_watt_hours>
        <battery_discharge_watt_hours>214</battery_discharge_watt_hours>
        <max_steer>0.8458</max_steer>
        <flwheel_steering_p_gain>1e4</flwheel_steering_p_gain>
        <frwheel_steering_p_gain>1e4</frwheel_steering_p_gain>
        <flwheel_steering_i_gain>0</flwheel_steering_i_gain>
        <frwheel_steering_i_gain>0</frwheel_steering_i_gain>
        <flwheel_steering_d_gain>3e2</flwheel_steering_d_gain>
        <frwheel_steering_d_gain>3e2</frwheel_steering_d_gain>
        <robotNamespace>/</robotNamespace>
      </plugin>
      <plugin name='joint_state_publisher' filename='libgazebo_ros_joint_state_publisher.so'>
        <jointName>rear_right_wheel_joint, rear_left_wheel_joint, front_right_wheel_joint, front_left_wheel_joint, front_right_steer_joint, front_left_steer_joint, steering_joint</jointName>
        <updateRate>100.0</updateRate>
        <alwaysOn>1</alwaysOn>
        <robotNamespace>/</robotNamespace>
      </plugin>
      <static>0</static>
      <plugin name='p3d' filename='libgazebo_ros_p3d.so'>
        <bodyName>pose_link</bodyName>
        <topicName>prius_slow</topicName>
        <frameName>map</frameName>
        <updateRate>100.0</updateRate>
        <robotNamespace>/</robotNamespace>
      </plugin>
      <pose frame=''>-20 -7.4518 0.006903 0 0.000236 0.104877</pose>
    </model>
  </world>
</sdf>
