<sdf version='1.6'>
  <world name='default'>
      <model name='camera_recorder'>
      <static>true</static>
      <pose>-38.1014 -5.22913 6.89088 0 0.385796 -0.003769</pose>
      <link name='cam_link'>
        <visual name='visual'>
          <geometry>
            <box>
              <size>0.1 0.1 0.1</size>
            </box>
          </geometry>
        </visual>
        <sensor name='my_camera' type='camera'>
          <camera>
            <save enabled="false">
              <path>/tmp/gazebo_camera</path>
            </save>
            <horizontal_fov>1.047</horizontal_fov>
            <image>
              <width>1920</width>
              <height>1080</height>
            </image>
            <clip>
              <near>0.1</near>
              <far>100</far>
            </clip>
          </camera>
          <always_on>1</always_on>
          <update_rate>30</update_rate>
        </sensor>
      </link>
    </model>   
    <gui fullscreen='0'>
      <plugin name='keyboard' filename='libKeyboardGUIPlugin.so'/>
      <camera name='user_camera'>
        <pose frame=''>-38.1014 -5.22913 6.89088 0 0.385796 -0.003769</pose>
        <view_controller>orbit</view_controller>
        <projection_type>perspective</projection_type>
      </camera>
    </gui>
    <light name='sun' type='directional'>
      <cast_shadows>1</cast_shadows>
      <pose frame=''>0 0 10 0 -0 0</pose>
      <diffuse>0.8 0.8 0.8 1</diffuse>
      <specular>0.2 0.2 0.2 1</specular>
      <attenuation>
        <range>1000</range>
        <constant>0.9</constant>
        <linear>0.01</linear>
        <quadratic>0.001</quadratic>
      </attenuation>
      <direction>-0.5 0.1 -0.9</direction>
    </light>
    <gravity>0 0 -9.8</gravity>
    <magnetic_field>6e-06 2.3e-05 -4.2e-05</magnetic_field>
    <atmosphere type='adiabatic'/>
    <physics name='default_physics' default='0' type='ode'>
      <max_step_size>0.001</max_step_size>
      <real_time_factor>1</real_time_factor>
      <real_time_update_rate>1000</real_time_update_rate>
    </physics>
    <scene>
      <ambient>0.4 0.4 0.4 1</ambient>
      <background>0.7 0.7 0.7 1</background>
      <sky/>
      <shadows>1</shadows>
    </scene>
    <audio>
      <device>default</device>
    </audio>
    <wind/>
    <spherical_coordinates>
      <surface_model>EARTH_WGS84</surface_model>
      <latitude_deg>0</latitude_deg>
      <longitude_deg>0</longitude_deg>
      <elevation>0</elevation>
      <heading_deg>0</heading_deg>
    </spherical_coordinates>
    <state world_name='default'>
      <sim_time>2917 208000000</sim_time>
      <real_time>78 918283801</real_time>
      <wall_time>1568118815 603412331</wall_time>
      <iterations>77627</iterations>
      <model name='ambulance'>
        <pose frame=''>-15.9191 -8.85985 0 0 -0 1.5601</pose>
        <scale>1 1 1</scale>
        <link name='link'>
          <pose frame=''>-15.9191 -8.85985 0 0 -0 1.5601</pose>
          <velocity>0 0 0 0 -0 0</velocity>
          <acceleration>0 0 0 0 -0 0</acceleration>
          <wrench>0 0 0 0 -0 0</wrench>
        </link>
      </model>
      <model name='ambulance_clone'>
        <pose frame=''>11.8282 -8.7272 0 0 -0 1.5601</pose>
        <scale>1 1 1</scale>
        <link name='link'>
          <pose frame=''>11.8282 -8.7272 0 0 -0 1.5601</pose>
          <velocity>0 0 0 0 -0 0</velocity>
          <acceleration>0 0 0 0 -0 0</acceleration>
          <wrench>0 0 0 0 -0 0</wrench>
        </link>
      </model>
      <model name='bus'>
        <pose frame=''>4.58331 3.71999 0 0 0 -1.57803</pose>
        <scale>1 1 1</scale>
        <link name='link'>
          <pose frame=''>4.58331 3.71999 0 0 0 -1.57803</pose>
          <velocity>0 0 0 0 -0 0</velocity>
          <acceleration>0 0 0 0 -0 0</acceleration>
          <wrench>0 0 0 0 -0 0</wrench>
        </link>
      </model>
      <model name='cloverleaf_interchange'>
        <pose frame=''>121.637 -0.690578 0 0 -0 0</pose>
        <scale>1 1 1</scale>
        <link name='link'>
          <pose frame=''>121.637 -0.690578 0 0 -0 0</pose>
          <velocity>0 0 0 0 -0 0</velocity>
          <acceleration>0 0 0 0 -0 0</acceleration>
          <wrench>0 0 0 0 -0 0</wrench>
        </link>
      </model>
      <model name='prius'>
        <pose frame=''>-15.0552 -4.95071 0.006902 0 0.000236 0.025037</pose>
        <scale>1 1 1</scale>
        <link name='base_link'>
          <pose frame=''>-15.0552 -4.95071 0.006902 0 0.000236 0.025037</pose>
          <velocity>-0.00913 -0.001156 -0.001886 0.000295 -0.011847 -0.053487</velocity>
          <acceleration>-2.9748 1.78234 0.00195 0.00208 -0.521189 2.47221</acceleration>
          <wrench>-2.9748 1.78234 0.00195 0 -0 0</wrench>
        </link>
        <link name='chassis'>
          <pose frame=''>-13.6057 -4.91433 0.007485 4.5e-05 -0 1.59508</pose>
          <velocity>-0.0072 -0.000246 -0.015331 0.000141 -0.005504 0.001038</velocity>
          <acceleration>0.672364 -0.001164 0.034505 0.031079 -1.47636 1.10675</acceleration>
          <wrench>921.811 -1.59644 47.306 0 -0 0</wrench>
        </link>
        <link name='fl_axle'>
          <pose frame=''>-12.2147 -4.11333 0.307607 0.002351 -2.8e-05 1.59378</pose>
          <velocity>-0.00566 0.001147 -0.029451 -0.00736 -0.116663 -2.37839</velocity>
          <acceleration>7.56316 1.51187 -0.177846 -2.25155 0.159838 -1.36807</acceleration>
          <wrench>7.56316 1.51187 -0.177846 0 -0 0</wrench>
        </link>
        <link name='fr_axle'>
          <pose frame=''>-12.1775 -5.64687 0.307607 0.002321 -2.5e-05 1.5938</pose>
          <velocity>-0.004123 0.001181 -0.02946 -0.007499 -0.11417 -2.34638</velocity>
          <acceleration>9.13119 1.54701 -0.184383 -2.55711 -1.2056 -0.170472</acceleration>
          <wrench>9.13119 1.54701 -0.184383 0 -0 0</wrench>
        </link>
        <link name='front_left_wheel'>
          <pose frame=''>-12.2147 -4.11333 0.307566 2.90254 -2e-05 1.59378</pose>
          <velocity>-0.005486 0.001144 -0.024576 -0.003717 -0.229134 -2.37839</velocity>
          <acceleration>8.0304 1.50725 -0.016244 0.22383 0.287723 -1.37044</acceleration>
          <wrench>88.3343 16.5798 -0.178679 0 -0 0</wrench>
        </link>
        <link name='front_right_wheel'>
          <pose frame=''>-12.1775 -5.64687 0.307566 2.83367 -1.8e-05 1.5938</pose>
          <velocity>-0.003952 0.001178 -0.024564 -0.003827 -0.225395 -2.34638</velocity>
          <acceleration>9.59302 1.542 -0.021939 3.11469 0.671 2.96788</acceleration>
          <wrench>105.523 16.9619 -0.241329 0 -0 0</wrench>
        </link>
        <link name='rear_left_wheel'>
          <pose frame=''>-15.0745 -4.15677 0.307555 2.32524 4e-06 1.59508</pose>
          <velocity>-0.008076 -0.001812 -0.02391 0.000268 -0.025796 0.001038</velocity>
          <acceleration>3.87271 -1.61738 -0.346413 -0.851682 0.767952 1.10665</acceleration>
          <wrench>42.5998 -17.7911 -3.81054 0 -0 0</wrench>
        </link>
        <link name='rear_right_wheel'>
          <pose frame=''>-15.036 -5.7423 0.307555 2.87934 3e-06 1.59508</pose>
          <velocity>-0.006813 -0.001781 -0.023881 0.000196 -0.02178 0.00104</velocity>
          <acceleration>4.85064 -1.59419 -0.342318 2.2496 0.084157 -2.03077</acceleration>
          <wrench>53.3571 -17.5361 -3.76549 0 -0 0</wrench>
        </link>
        <link name='steering_wheel'>
          <pose frame=''>-12.9866 -4.54146 0.995699 -1.30205 -0 1.59508</pose>
          <velocity>-0.013068 0.000257 -0.011792 0.000323 -0.005559 0.000989</velocity>
          <acceleration>0.051686 0.676968 0.257953 0.386236 -0.350658 0.8562</acceleration>
          <wrench>0.051686 0.676968 0.257953 0 -0 0</wrench>
        </link>
      </model>
      <model name='prius_clone'>
        <pose frame=''>-24.3381 -4.95426 0.007919 -0.000159 0.000612 0.121363</pose>
        <scale>1 1 1</scale>
        <link name='base_link'>
          <pose frame=''>-24.3381 -4.95426 0.007919 -0.000159 0.000612 0.121363</pose>
          <velocity>-0.008503 -0.000739 -0.00229 0.006007 -0.014727 -0.053236</velocity>
          <acceleration>-11.5791 -0.002498 0.01084 -0.031702 -0.049849 2.26112</acceleration>
          <wrench>-11.5791 -0.002498 0.01084 0 -0 0</wrench>
        </link>
        <link name='chassis'>
          <pose frame=''>-22.8988 -4.77865 0.007992 0.000413 0.000159 1.69141</pose>
          <velocity>-0.003001 0.003212 -0.017224 0.005102 -0.007079 0.001691</velocity>
          <acceleration>0.031149 0.040147 0.001273 0.017402 -0.132986 0.976272</acceleration>
          <wrench>42.7052 55.0414 1.74566 0 -0 0</wrench>
        </link>
        <link name='fl_axle'>
          <pose frame=''>-21.5912 -3.84751 0.307592 0.002293 0.000165 1.69056</pose>
          <velocity>-0.009864 0.004377 -0.042816 0.030393 0.092804 -1.85138</velocity>
          <acceleration>-7.48606 2.24502 -0.031283 -0.851627 1.02461 -1.15704</acceleration>
          <wrench>-7.48606 2.24502 -0.031283 0 -0 0</wrench>
        </link>
        <link name='fr_axle'>
          <pose frame=''>-21.4066 -5.37037 0.307618 0.002284 0.000166 1.69035</pose>
          <velocity>-0.000444 0.003772 -0.016825 -0.033525 -0.104526 -1.92976</velocity>
          <acceleration>7.65066 0.600402 -0.027498 -2.02189 -0.555122 -0.852101</acceleration>
          <wrench>7.65066 0.600402 -0.027498 0 -0 0</wrench>
        </link>
        <link name='front_left_wheel'>
          <pose frame=''>-21.5912 -3.84751 0.307524 2.96483 0.000163 1.69056</pose>
          <velocity>-0.010035 0.004379 -0.034002 0.036122 -0.032895 -1.85133</velocity>
          <acceleration>-7.70107 2.29467 -0.011084 -0.402931 -0.26601 2.05697</acceleration>
          <wrench>-84.7118 25.2414 -0.121919 0 -0 0</wrench>
        </link>
        <link name='front_right_wheel'>
          <pose frame=''>-21.4066 -5.37037 0.307599 0.183044 0.000166 1.69035</pose>
          <velocity>-0.000397 0.003741 -0.015184 -0.012111 -0.193512 -1.92979</velocity>
          <acceleration>7.87539 0.583273 -0.011514 -2.02659 -0.989844 2.19439</acceleration>
          <wrench>86.6293 6.41601 -0.126652 0 -0 0</wrench>
        </link>
        <link name='rear_left_wheel'>
          <pose frame=''>-24.4336 -4.16581 0.308465 -1.12422 0.000149 1.69141</pose>
          <velocity>-0.004776 -0.001153 -0.0247 0.001962 -0.015303 0.001687</velocity>
          <acceleration>0.782674 -1.18402 -0.021365 -0.045748 1.16244 -2.17111</acceleration>
          <wrench>8.60941 -13.0242 -0.235011 0 -0 0</wrench>
        </link>
        <link name='rear_right_wheel'>
          <pose frame=''>-24.2427 -5.74028 0.308725 -0.678052 0.000121 1.69141</pose>
          <velocity>-0.004884 -0.001065 -0.032702 0.003289 -0.015589 0.001317</velocity>
          <acceleration>0.621592 -0.978671 -0.035576 -0.741037 1.43669 0.866485</acceleration>
          <wrench>6.83751 -10.7654 -0.391339 0 -0 0</wrench>
        </link>
        <link name='steering_wheel'>
          <pose frame=''>-22.3181 -4.34776 0.995918 -1.30169 0.000159 1.69141</pose>
          <velocity>-0.010765 -0.000854 -0.010821 0.001392 -0.007613 0.002725</velocity>
          <acceleration>-0.406966 0.594494 0.025918 0.360112 0.009909 0.748987</acceleration>
          <wrench>-0.406966 0.594494 0.025918 0 -0 0</wrench>
        </link>
      </model>
      <model name='suv'>
        <pose frame=''>-14.9166 3.82029 0 0 0 -3.13734</pose>
        <scale>1 1 1</scale>
        <link name='link'>
          <pose frame=''>-14.9166 3.82029 0 0 -0 -3.13734</pose>
          <velocity>0 0 0 0 -0 0</velocity>
          <acceleration>0 0 0 0 -0 0</acceleration>
          <wrench>0 0 0 0 -0 0</wrench>
        </link>
      </model>
      <model name='suv_0'>
        <pose frame=''>-31.201 -4.98139 0 0 -0 0</pose>
        <scale>1 1 1</scale>
        <link name='link'>
          <pose frame=''>-31.201 -4.98139 0 0 -0 0</pose>
          <velocity>0 0 0 0 -0 0</velocity>
          <acceleration>0 0 0 0 -0 0</acceleration>
          <wrench>0 0 0 0 -0 0</wrench>
        </link>
      </model>
      <light name='sun'>
        <pose frame=''>0.5 0 1 0 -0 0</pose>
      </light>
    </state>
    <model name='cloverleaf_interchange'>
      <static>1</static>
      <link name='link'>
        <collision name='collision'>
          <geometry>
            <mesh>
              <uri>model://cloverleaf_interchange/meshes/cloverleaf.obj</uri>
              <scale>0.0254 0.0254 0.0254</scale>
            </mesh>
          </geometry>
          <max_contacts>10</max_contacts>
          <surface>
            <contact>
              <ode/>
            </contact>
            <bounce/>
            <friction>
              <torsional>
                <ode/>
              </torsional>
              <ode/>
            </friction>
          </surface>
        </collision>
        <visual name='visual'>
          <geometry>
            <mesh>
              <uri>model://cloverleaf_interchange/meshes/cloverleaf.obj</uri>
              <scale>0.0254 0.0254 0.0254</scale>
            </mesh>
          </geometry>
        </visual>
        <self_collide>0</self_collide>
        <enable_wind>0</enable_wind>
        <kinematic>0</kinematic>
      </link>
      <pose frame=''>-295.324 348.572 0 0 -0 0</pose>
    </model>
    <gui fullscreen='0'>
      <camera name='user_camera'>
        <pose frame=''>164.478 -122.879 113.552 0 0.517796 2.38416</pose>
        <view_controller>orbit</view_controller>
        <projection_type>perspective</projection_type>
      </camera>
    </gui>
    <model name='suv'>
      <static>1</static>
      <link name='link'>
        <collision name='collision'>
          <pose frame=''>0 0 0 0 0 -1.5708</pose>
          <geometry>
            <mesh>
              <scale>0.06 0.06 0.06</scale>
              <uri>model://suv/meshes/suv.obj</uri>
            </mesh>
          </geometry>
          <max_contacts>10</max_contacts>
          <surface>
            <contact>
              <ode/>
            </contact>
            <bounce/>
            <friction>
              <torsional>
                <ode/>
              </torsional>
              <ode/>
            </friction>
          </surface>
        </collision>
        <visual name='visual'>
          <pose frame=''>0 0 0 0 0 -1.5708</pose>
          <geometry>
            <mesh>
              <scale>0.06 0.06 0.06</scale>
              <uri>model://suv/meshes/suv.obj</uri>
            </mesh>
          </geometry>
        </visual>
        <self_collide>0</self_collide>
        <enable_wind>0</enable_wind>
        <kinematic>0</kinematic>
      </link>
      <pose frame=''>-146.945 353.006 0 0 -0 0</pose>
    </model>
    <model name='ambulance'>
      <static>1</static>
      <link name='link'>
        <collision name='collision'>
          <geometry>
            <mesh>
              <scale>0.0254 0.0254 0.0254</scale>
              <uri>model://ambulance/meshes/ambulance.obj</uri>
            </mesh>
          </geometry>
          <max_contacts>10</max_contacts>
          <surface>
            <contact>
              <ode/>
            </contact>
            <bounce/>
            <friction>
              <torsional>
                <ode/>
              </torsional>
              <ode/>
            </friction>
          </surface>
        </collision>
        <visual name='visual'>
          <geometry>
            <mesh>
              <scale>0.0254 0.0254 0.0254</scale>
              <uri>model://ambulance/meshes/ambulance.obj</uri>
            </mesh>
          </geometry>
        </visual>
        <self_collide>0</self_collide>
        <enable_wind>0</enable_wind>
        <kinematic>0</kinematic>
      </link>
      <pose frame=''>-147.617 342.063 0 0 -0 0</pose>
    </model>
    <model name='ambulance_clone'>
      <static>1</static>
      <link name='link'>
        <collision name='collision'>
          <geometry>
            <mesh>
              <scale>0.0254 0.0254 0.0254</scale>
              <uri>model://ambulance/meshes/ambulance.obj</uri>
            </mesh>
          </geometry>
          <max_contacts>10</max_contacts>
          <surface>
            <contact>
              <ode/>
            </contact>
            <bounce/>
            <friction>
              <torsional>
                <ode/>
              </torsional>
              <ode/>
            </friction>
          </surface>
        </collision>
        <visual name='visual'>
          <geometry>
            <mesh>
              <scale>0.0254 0.0254 0.0254</scale>
              <uri>model://ambulance/meshes/ambulance.obj</uri>
            </mesh>
          </geometry>
        </visual>
        <self_collide>0</self_collide>
        <enable_wind>0</enable_wind>
        <kinematic>0</kinematic>
      </link>
      <pose frame=''>11.8282 -8.7272 0 0 -0 1.5601</pose>
    </model>
    <model name='bus'>
      <static>1</static>
      <link name='link'>
        <collision name='collision'>
          <geometry>
            <mesh>
              <scale>0.01 0.01 0.01</scale>
              <uri>model://bus/meshes/bus.obj</uri>
            </mesh>
          </geometry>
          <max_contacts>10</max_contacts>
          <surface>
            <contact>
              <ode/>
            </contact>
            <bounce/>
            <friction>
              <torsional>
                <ode/>
              </torsional>
              <ode/>
            </friction>
          </surface>
        </collision>
        <visual name='visual'>
          <geometry>
            <mesh>
              <scale>0.01 0.01 0.01</scale>
              <uri>model://bus/meshes/bus.obj</uri>
            </mesh>
          </geometry>
        </visual>
        <self_collide>0</self_collide>
        <enable_wind>0</enable_wind>
        <kinematic>0</kinematic>
      </link>
      <pose frame=''>-25.5284 5.85362 0 0 -0 0</pose>
    </model>
    <model name='suv_0'>
      <static>1</static>
      <link name='link'>
        <collision name='collision'>
          <pose frame=''>0 0 0 0 0 -1.5708</pose>
          <geometry>
            <mesh>
              <scale>0.06 0.06 0.06</scale>
              <uri>model://suv/meshes/suv.obj</uri>
            </mesh>
          </geometry>
          <max_contacts>10</max_contacts>
          <surface>
            <contact>
              <ode/>
            </contact>
            <bounce/>
            <friction>
              <torsional>
                <ode/>
              </torsional>
              <ode/>
            </friction>
          </surface>
        </collision>
        <visual name='visual'>
          <pose frame=''>0 0 0 0 0 -1.5708</pose>
          <geometry>
            <mesh>
              <scale>0.06 0.06 0.06</scale>
              <uri>model://suv/meshes/suv.obj</uri>
            </mesh>
          </geometry>
        </visual>
        <self_collide>0</self_collide>
        <enable_wind>0</enable_wind>
        <kinematic>0</kinematic>
      </link>
      <pose frame=''>-31.201 -4.98139 0 0 -0 0</pose>
    </model>
    <model name='prius'>
      <link name='base_link'>
        <pose frame=''>0 0 0 0 -0 0</pose>
        <inertial>
          <pose frame=''>0 0 0 0 -0 0</pose>
          <mass>1</mass>
          <inertia>
            <ixx>0.001</ixx>
            <ixy>0</ixy>
            <ixz>0</ixz>
            <iyy>0.001</iyy>
            <iyz>0</iyz>
            <izz>0.001</izz>
          </inertia>
        </inertial>
        <self_collide>0</self_collide>
        <enable_wind>0</enable_wind>
        <kinematic>0</kinematic>
      </link>
      <link name='chassis'>
        <pose frame=''>1.45 0 0 0 -0 1.57</pose>
        <inertial>
          <pose frame=''>-0 -0.002735 0.483209 0 -0 1.5708</pose>
          <mass>1371</mass>
          <inertia>
            <ixx>2591.3</ixx>
            <ixy>0.000184475</ixy>
            <ixz>-0.702035</ixz>
            <iyy>651.702</iyy>
            <iyz>2.57872e-06</iyz>
            <izz>2744.57</izz>
          </inertia>
        </inertial>
        <collision name='chassis_fixed_joint_lump__back_bumper_collision_8'>
          <pose frame=''>0 2.05445 0.57787 0 -0 0</pose>
          <geometry>
            <box>
              <size>1.78165 0.512093 0.581427</size>
            </box>
          </geometry>
          <max_contacts>10</max_contacts>
          <surface>
            <contact>
              <ode/>
            </contact>
            <bounce/>
            <friction>
              <torsional>
                <ode/>
              </torsional>
              <ode/>
            </friction>
          </surface>
        </collision>
        <visual name='chassis_visual'>
          <pose frame=''>0 0 0 0 -0 0</pose>
          <geometry>
            <mesh>
              <scale>0.01 0.01 0.01</scale>
              <uri>/home/kostas/datmo_ws/src/car_demo-master/prius_description/meshes/hybrid_body.obj</uri>
            </mesh>
          </geometry>
        </visual>
        <velocity_decay/>
        <sensor name='center_laser_sensor' type='ray'>
          <ray>
            <scan>
              <horizontal>
                <samples>360</samples>
                <resolution>1</resolution>
                <min_angle>-3.14</min_angle>
                <max_angle>3.14</max_angle>
              </horizontal>
              <vertical>
                <samples>1</samples>
                <min_angle>0</min_angle>
                <max_angle>0</max_angle>
              </vertical>
            </scan>
            <range>
              <min>0.2</min>
              <max>50</max>
              <resolution>0.01</resolution>
            </range>
          </ray>
          <plugin name='center_laser' filename='libgazebo_ros_laser.so'>
            <topicName>/scan</topicName>
            <frameName>center_laser_link</frameName>
            <robotNamespace>/</robotNamespace>
          </plugin>
          <always_on>1</always_on>
          <update_rate>12</update_rate>
          <visualize>0</visualize>
          <pose frame=''>0 0.4 0.9 0 0 -1.5707</pose>
        </sensor>
        <velocity_decay/>
        <self_collide>0</self_collide>
        <enable_wind>0</enable_wind>
        <kinematic>0</kinematic>
      </link>
      <joint name='base_link_connection' type='revolute'>
        <child>chassis</child>
        <parent>base_link</parent>
        <axis>
          <limit>
            <lower>0</lower>
            <upper>0</upper>
          </limit>
          <dynamics>
            <damping>0</damping>
            <friction>0</friction>
            <spring_reference>0</spring_reference>
            <spring_stiffness>0</spring_stiffness>
          </dynamics>
          <use_parent_model_frame>1</use_parent_model_frame>
          <xyz>0 0 1</xyz>
        </axis>
        <physics>
          <ode>
            <limit>
              <cfm>0</cfm>
              <erp>0.2</erp>
            </limit>
          </ode>
        </physics>
      </joint>
      <link name='fl_axle'>
        <pose frame=''>2.86061 0.765877 0.3 0 -0 1.57</pose>
        <inertial>
          <pose frame=''>0 0 0 0 -0 0</pose>
          <mass>1</mass>
          <inertia>
            <ixx>0.004</ixx>
            <ixy>0</ixy>
            <ixz>0</ixz>
            <iyy>0.004</iyy>
            <iyz>0</iyz>
            <izz>0.004</izz>
          </inertia>
        </inertial>
        <self_collide>0</self_collide>
        <enable_wind>0</enable_wind>
        <kinematic>0</kinematic>
      </link>
      <joint name='front_left_steer_joint' type='revolute'>
        <child>fl_axle</child>
        <parent>chassis</parent>
        <axis>
          <xyz>0 0 1</xyz>
          <limit>
            <lower>-1e+16</lower>
            <upper>1e+16</upper>
          </limit>
          <dynamics>
            <spring_reference>0</spring_reference>
            <spring_stiffness>0</spring_stiffness>
          </dynamics>
          <use_parent_model_frame>1</use_parent_model_frame>
        </axis>
      </joint>
      <link name='front_left_wheel'>
        <pose frame=''>2.86061 0.765877 0.3 0 -0 1.57</pose>
        <inertial>
          <pose frame=''>0 0 0 0 -0 0</pose>
          <mass>11</mass>
          <inertia>
            <ixx>0.586312</ixx>
            <ixy>0</ixy>
            <ixz>0</ixz>
            <iyy>0.335529</iyy>
            <iyz>0</iyz>
            <izz>0.335529</izz>
          </inertia>
        </inertial>
        <collision name='front_left_wheel_collision_collision'>
          <pose frame=''>0 0 0 0 -0 0</pose>
          <geometry>
            <sphere>
              <radius>0.31265</radius>
            </sphere>
          </geometry>
          <surface>
            <contact>
              <ode>
                <kp>1e+08</kp>
                <min_depth>0.005</min_depth>
              </ode>
            </contact>
            <friction>
              <ode>
                <mu>0.9</mu>
                <mu2>0.9</mu2>
              </ode>
              <torsional>
                <ode/>
              </torsional>
            </friction>
            <bounce/>
          </surface>
          <max_contacts>10</max_contacts>
        </collision>
        <visual name='front_left_wheel_visual'>
          <pose frame=''>0 0 0 0 -0 0</pose>
          <geometry>
            <mesh>
              <scale>0.01 0.01 0.01</scale>
              <uri>/home/kostas/datmo_ws/src/car_demo-master/prius_description/meshes/wheel.obj</uri>
            </mesh>
          </geometry>
          <material>
            <script>
              <uri>__default__</uri>
              <name>__default__</name>
            </script>
          </material>
        </visual>
        <gravity>1</gravity>
        <velocity_decay/>
        <self_collide>0</self_collide>
        <enable_wind>0</enable_wind>
        <kinematic>0</kinematic>
      </link>
      <joint name='front_left_wheel_joint' type='revolute'>
        <child>front_left_wheel</child>
        <parent>fl_axle</parent>
        <axis>
          <xyz>0.000796 1 0</xyz>
          <limit>
            <lower>-1e+16</lower>
            <upper>1e+16</upper>
          </limit>
          <dynamics>
            <spring_reference>0</spring_reference>
            <spring_stiffness>0</spring_stiffness>
          </dynamics>
          <use_parent_model_frame>1</use_parent_model_frame>
        </axis>
      </joint>
      <link name='fr_axle'>
        <pose frame=''>2.85939 -0.768123 0.3 0 -0 1.57</pose>
        <inertial>
          <pose frame=''>0 0 0 0 -0 0</pose>
          <mass>1</mass>
          <inertia>
            <ixx>0.004</ixx>
            <ixy>0</ixy>
            <ixz>0</ixz>
            <iyy>0.004</iyy>
            <iyz>0</iyz>
            <izz>0.004</izz>
          </inertia>
        </inertial>
        <self_collide>0</self_collide>
        <enable_wind>0</enable_wind>
        <kinematic>0</kinematic>
      </link>
      <joint name='front_right_steer_joint' type='revolute'>
        <child>fr_axle</child>
        <parent>chassis</parent>
        <axis>
          <xyz>0 0 1</xyz>
          <limit>
            <lower>-1e+16</lower>
            <upper>1e+16</upper>
          </limit>
          <dynamics>
            <spring_reference>0</spring_reference>
            <spring_stiffness>0</spring_stiffness>
          </dynamics>
          <use_parent_model_frame>1</use_parent_model_frame>
        </axis>
      </joint>
      <link name='front_right_wheel'>
        <pose frame=''>2.85939 -0.768123 0.3 0 -0 1.57</pose>
        <inertial>
          <pose frame=''>0 0 0 0 -0 0</pose>
          <mass>11</mass>
          <inertia>
            <ixx>0.586312</ixx>
            <ixy>0</ixy>
            <ixz>0</ixz>
            <iyy>0.335529</iyy>
            <iyz>0</iyz>
            <izz>0.335529</izz>
          </inertia>
        </inertial>
        <collision name='front_right_wheel_collision_collision'>
          <pose frame=''>0 0 0 0 -0 0</pose>
          <geometry>
            <sphere>
              <radius>0.31265</radius>
            </sphere>
          </geometry>
          <surface>
            <contact>
              <ode>
                <kp>1e+08</kp>
                <min_depth>0.005</min_depth>
              </ode>
            </contact>
            <friction>
              <ode>
                <mu>0.9</mu>
                <mu2>0.9</mu2>
              </ode>
              <torsional>
                <ode/>
              </torsional>
            </friction>
            <bounce/>
          </surface>
          <max_contacts>10</max_contacts>
        </collision>
        <visual name='front_right_wheel_visual'>
          <pose frame=''>0 0 0 0 -0 0</pose>
          <geometry>
            <mesh>
              <scale>0.01 0.01 0.01</scale>
              <uri>/home/kostas/datmo_ws/src/car_demo-master/prius_description/meshes/wheel.obj</uri>
            </mesh>
          </geometry>
          <material>
            <script>
              <uri>__default__</uri>
              <name>__default__</name>
            </script>
          </material>
        </visual>
        <gravity>1</gravity>
        <velocity_decay/>
        <self_collide>0</self_collide>
        <enable_wind>0</enable_wind>
        <kinematic>0</kinematic>
      </link>
      <joint name='front_right_wheel_joint' type='revolute'>
        <child>front_right_wheel</child>
        <parent>fr_axle</parent>
        <axis>
          <xyz>0.000796 1 0</xyz>
          <limit>
            <lower>-1e+16</lower>
            <upper>1e+16</upper>
          </limit>
          <dynamics>
            <spring_reference>0</spring_reference>
            <spring_stiffness>0</spring_stiffness>
          </dynamics>
          <use_parent_model_frame>1</use_parent_model_frame>
        </axis>
      </joint>
      <link name='rear_left_wheel'>
        <pose frame=''>0.000632 0.794154 0.3 0 -0 1.57</pose>
        <inertial>
          <pose frame=''>0 0 0 0 -0 0</pose>
          <mass>11</mass>
          <inertia>
            <ixx>0.586312</ixx>
            <ixy>0</ixy>
            <ixz>0</ixz>
            <iyy>0.335529</iyy>
            <iyz>0</iyz>
            <izz>0.335529</izz>
          </inertia>
        </inertial>
        <collision name='rear_left_wheel_collision_collision'>
          <pose frame=''>0 0 0 0 -0 0</pose>
          <geometry>
            <sphere>
              <radius>0.31265</radius>
            </sphere>
          </geometry>
          <surface>
            <contact>
              <ode>
                <kp>1e+08</kp>
                <min_depth>0.005</min_depth>
              </ode>
            </contact>
            <friction>
              <ode>
                <mu>0.9</mu>
                <mu2>0.9</mu2>
              </ode>
              <torsional>
                <ode/>
              </torsional>
            </friction>
            <bounce/>
          </surface>
          <max_contacts>10</max_contacts>
        </collision>
        <visual name='rear_left_wheel_visual'>
          <pose frame=''>0 0 0 0 -0 0</pose>
          <geometry>
            <mesh>
              <scale>0.01 0.01 0.01</scale>
              <uri>/home/kostas/datmo_ws/src/car_demo-master/prius_description/meshes/wheel.obj</uri>
            </mesh>
          </geometry>
          <material>
            <script>
              <uri>__default__</uri>
              <name>__default__</name>
            </script>
          </material>
        </visual>
        <gravity>1</gravity>
        <velocity_decay/>
        <self_collide>0</self_collide>
        <enable_wind>0</enable_wind>
        <kinematic>0</kinematic>
      </link>
      <joint name='rear_left_wheel_joint' type='revolute'>
        <child>rear_left_wheel</child>
        <parent>chassis</parent>
        <axis>
          <xyz>0.000796 1 0</xyz>
          <limit>
            <lower>-1e+16</lower>
            <upper>1e+16</upper>
          </limit>
          <dynamics>
            <spring_reference>0</spring_reference>
            <spring_stiffness>0</spring_stiffness>
          </dynamics>
          <use_parent_model_frame>1</use_parent_model_frame>
        </axis>
      </joint>
      <link name='rear_right_wheel'>
        <pose frame=''>-0.000631 -0.791845 0.3 0 -0 1.57</pose>
        <inertial>
          <pose frame=''>0 0 0 0 -0 0</pose>
          <mass>11</mass>
          <inertia>
            <ixx>0.586312</ixx>
            <ixy>0</ixy>
            <ixz>0</ixz>
            <iyy>0.335529</iyy>
            <iyz>0</iyz>
            <izz>0.335529</izz>
          </inertia>
        </inertial>
        <collision name='rear_right_wheel_collision_collision'>
          <pose frame=''>0 0 0 0 -0 0</pose>
          <geometry>
            <sphere>
              <radius>0.31265</radius>
            </sphere>
          </geometry>
          <surface>
            <contact>
              <ode>
                <kp>1e+08</kp>
                <min_depth>0.005</min_depth>
              </ode>
            </contact>
            <friction>
              <ode>
                <mu>0.9</mu>
                <mu2>0.9</mu2>
              </ode>
              <torsional>
                <ode/>
              </torsional>
            </friction>
            <bounce/>
          </surface>
          <max_contacts>10</max_contacts>
        </collision>
        <visual name='rear_right_wheel_visual'>
          <pose frame=''>0 0 0 0 -0 0</pose>
          <geometry>
            <mesh>
              <scale>0.01 0.01 0.01</scale>
              <uri>/home/kostas/datmo_ws/src/car_demo-master/prius_description/meshes/wheel.obj</uri>
            </mesh>
          </geometry>
          <material>
            <script>
              <uri>__default__</uri>
              <name>__default__</name>
            </script>
          </material>
        </visual>
        <gravity>1</gravity>
        <velocity_decay/>
        <self_collide>0</self_collide>
        <enable_wind>0</enable_wind>
        <kinematic>0</kinematic>
      </link>
      <joint name='rear_right_wheel_joint' type='revolute'>
        <child>rear_right_wheel</child>
        <parent>chassis</parent>
        <axis>
          <xyz>0.000796 1 0</xyz>
          <limit>
            <lower>-1e+16</lower>
            <upper>1e+16</upper>
          </limit>
          <dynamics>
            <spring_reference>0</spring_reference>
            <spring_stiffness>0</spring_stiffness>
          </dynamics>
          <use_parent_model_frame>1</use_parent_model_frame>
        </axis>
      </joint>
      <link name='steering_wheel'>
        <pose frame=''>2.07815 0.357234 0.988243 -1.3021 0 1.57</pose>
        <inertial>
          <pose frame=''>0 0 0 0 -0 0</pose>
          <mass>1</mass>
          <inertia>
            <ixx>0.145833</ixx>
            <ixy>0</ixy>
            <ixz>0</ixz>
            <iyy>0.145833</iyy>
            <iyz>0</iyz>
            <izz>0.125</izz>
          </inertia>
        </inertial>
        <visual name='steering_wheel_visual'>
          <pose frame=''>0 0 0 1.3021 -0 0</pose>
          <geometry>
            <mesh>
              <scale>0.01 0.01 0.01</scale>
              <uri>/home/kostas/datmo_ws/src/car_demo-master/prius_description/meshes/steering_wheel.obj</uri>
            </mesh>
          </geometry>
        </visual>
        <self_collide>0</self_collide>
        <enable_wind>0</enable_wind>
        <kinematic>0</kinematic>
      </link>
      <joint name='steering_joint' type='revolute'>
        <child>steering_wheel</child>
        <parent>chassis</parent>
        <axis>
          <xyz>-0.964118 0.000768 0.265474</xyz>
          <limit>
            <lower>-1e+16</lower>
            <upper>1e+16</upper>
          </limit>
          <dynamics>
            <spring_reference>0</spring_reference>
            <spring_stiffness>0</spring_stiffness>
          </dynamics>
          <use_parent_model_frame>1</use_parent_model_frame>
        </axis>
      </joint>
      <plugin name='pruis_hybrid_drive' filename='libActor.so'>
        <chassis>chassis</chassis>
        <front_left_wheel>front_left_wheel_joint</front_left_wheel>
        <front_right_wheel>front_right_wheel_joint</front_right_wheel>
        <front_left_wheel_steering>front_left_steer_joint</front_left_wheel_steering>
        <front_right_wheel_steering>front_right_steer_joint</front_right_wheel_steering>
        <back_left_wheel>rear_left_wheel_joint</back_left_wheel>
        <back_right_wheel>rear_right_wheel_joint</back_right_wheel>
        <steering_wheel>steering_joint</steering_wheel>
        <chassis_aero_force_gain>0.63045</chassis_aero_force_gain>
        <front_torque>859.4004393000001</front_torque>
        <back_torque>0</back_torque>
        <front_brake_torque>1031.28052716</front_brake_torque>
        <back_brake_torque>687.5203514400001</back_brake_torque>
        <max_speed>37.998337013956565</max_speed>
        <min_gas_flow>8.981854013171626e-05</min_gas_flow>
        <gas_efficiency>0.371</gas_efficiency>
        <battery_charge_watt_hours>291</battery_charge_watt_hours>
        <battery_discharge_watt_hours>214</battery_discharge_watt_hours>
        <max_steer>0.8458</max_steer>
        <flwheel_steering_p_gain>1e4</flwheel_steering_p_gain>
        <frwheel_steering_p_gain>1e4</frwheel_steering_p_gain>
        <flwheel_steering_i_gain>0</flwheel_steering_i_gain>
        <frwheel_steering_i_gain>0</frwheel_steering_i_gain>
        <flwheel_steering_d_gain>3e2</flwheel_steering_d_gain>
        <frwheel_steering_d_gain>3e2</frwheel_steering_d_gain>
        <robotNamespace>/</robotNamespace>
      </plugin>
      <plugin name='joint_state_publisher' filename='libgazebo_ros_joint_state_publisher.so'>
        <jointName>rear_right_wheel_joint, rear_left_wheel_joint, front_right_wheel_joint, front_left_wheel_joint, front_right_steer_joint, front_left_steer_joint, steering_joint</jointName>
        <updateRate>100.0</updateRate>
        <alwaysOn>1</alwaysOn>
        <robotNamespace>/</robotNamespace>
      </plugin>
      <static>0</static>
      <plugin name='p3d' filename='libgazebo_ros_p3d.so'>
        <bodyName>base_link</bodyName>
        <topicName>mocap_pose</topicName>
        <frameName>map</frameName>
        <updateRate>100.0</updateRate>
        <robotNamespace>/</robotNamespace>
      </plugin>
      <pose frame=''>1 -2 0.5 0 -0 0</pose>
    </model>
    <model name='prius_clone'>
      <link name='base_link'>
        <pose frame=''>0 0 0 0 -0 0</pose>
        <inertial>
          <pose frame=''>0 0 0 0 -0 0</pose>
          <mass>1</mass>
          <inertia>
            <ixx>0.001</ixx>
            <ixy>0</ixy>
            <ixz>0</ixz>
            <iyy>0.001</iyy>
            <iyz>0</iyz>
            <izz>0.001</izz>
          </inertia>
        </inertial>
        <self_collide>0</self_collide>
        <enable_wind>0</enable_wind>
        <kinematic>0</kinematic>
      </link>
      <link name='chassis'>
        <pose frame=''>1.45 0 0 0 -0 1.57</pose>
        <inertial>
          <pose frame=''>-0 -0.002735 0.483209 0 -0 1.5708</pose>
          <mass>1371</mass>
          <inertia>
            <ixx>2591.3</ixx>
            <ixy>0.000184475</ixy>
            <ixz>-0.702035</ixz>
            <iyy>651.702</iyy>
            <iyz>2.57872e-06</iyz>
            <izz>2744.57</izz>
          </inertia>
        </inertial>
        <collision name='chassis_collision'>
          <pose frame=''>0 0.05 0.625 0 -0 0</pose>
          <geometry>
            <box>
              <size>1.7526 2.1 0.95</size>
            </box>
          </geometry>
          <max_contacts>10</max_contacts>
          <surface>
            <contact>
              <ode/>
            </contact>
            <bounce/>
            <friction>
              <torsional>
                <ode/>
              </torsional>
              <ode/>
            </friction>
          </surface>
        </collision>
        <collision name='chassis_fixed_joint_lump__front_bumper_collision_1'>
          <pose frame=''>0 -2 0.458488 0 -0 0</pose>
          <geometry>
            <box>
              <size>1.33728 0.48 0.566691</size>
            </box>
          </geometry>
          <max_contacts>10</max_contacts>
          <surface>
            <contact>
              <ode/>
            </contact>
            <bounce/>
            <friction>
              <torsional>
                <ode/>
              </torsional>
              <ode/>
            </friction>
          </surface>
        </collision>
        <collision name='chassis_fixed_joint_lump__hood_collision_2'>
          <pose frame=''>0 -1.90084 0.676305 0.341247 -0 0</pose>
          <geometry>
            <box>
              <size>1.59797 0.493107 0.265468</size>
            </box>
          </geometry>
          <max_contacts>10</max_contacts>
          <surface>
            <contact>
              <ode/>
            </contact>
            <bounce/>
            <friction>
              <torsional>
                <ode/>
              </torsional>
              <ode/>
            </friction>
          </surface>
        </collision>
        <collision name='chassis_fixed_joint_lump__windshield_collision_3'>
          <pose frame=''>0 -0.875105 1.03227 0.335476 -0 0</pose>
          <geometry>
            <box>
              <size>1.16838 1.65425 0.272347</size>
            </box>
          </geometry>
          <max_contacts>10</max_contacts>
          <surface>
            <contact>
              <ode/>
            </contact>
            <bounce/>
            <friction>
              <torsional>
                <ode/>
              </torsional>
              <ode/>
            </friction>
          </surface>
        </collision>
        <collision name='chassis_fixed_joint_lump__top_front_collision_4'>
          <pose frame=''>0 0.161236 1.38604 0.13503 -0 0</pose>
          <geometry>
            <box>
              <size>1.27915 0.625988 0.171868</size>
            </box>
          </geometry>
          <max_contacts>10</max_contacts>
          <surface>
            <contact>
              <ode/>
            </contact>
            <bounce/>
            <friction>
              <torsional>
                <ode/>
              </torsional>
              <ode/>
            </friction>
          </surface>
        </collision>
        <collision name='chassis_fixed_joint_lump__top_rear_collision_5'>
          <pose frame=''>0 0.817696 1.36007 -0.068997 0 0</pose>
          <geometry>
            <box>
              <size>1.28513 0.771189 0.226557</size>
            </box>
          </geometry>
          <max_contacts>10</max_contacts>
          <surface>
            <contact>
              <ode/>
            </contact>
            <bounce/>
            <friction>
              <torsional>
                <ode/>
              </torsional>
              <ode/>
            </friction>
          </surface>
        </collision>
        <collision name='chassis_fixed_joint_lump__rear_window_collision_6'>
          <pose frame=''>0 1.64053 1.17513 -0.262017 0 0</pose>
          <geometry>
            <box>
              <size>1.26785 1.11634 0.244286</size>
            </box>
          </geometry>
          <max_contacts>10</max_contacts>
          <surface>
            <contact>
              <ode/>
            </contact>
            <bounce/>
            <friction>
              <torsional>
                <ode/>
              </torsional>
              <ode/>
            </friction>
          </surface>
        </collision>
        <collision name='chassis_fixed_joint_lump__trunk_collision_7'>
          <pose frame=''>0 1.63706 0.88818 0 -0 0</pose>
          <geometry>
            <box>
              <size>1.78806 1.13899 0.482746</size>
            </box>
          </geometry>
          <max_contacts>10</max_contacts>
          <surface>
            <contact>
              <ode/>
            </contact>
            <bounce/>
            <friction>
              <torsional>
                <ode/>
              </torsional>
              <ode/>
            </friction>
          </surface>
        </collision>
        <collision name='chassis_fixed_joint_lump__back_bumper_collision_8'>
          <pose frame=''>0 2.05445 0.57787 0 -0 0</pose>
          <geometry>
            <box>
              <size>1.78165 0.512093 0.581427</size>
            </box>
          </geometry>
          <max_contacts>10</max_contacts>
          <surface>
            <contact>
              <ode/>
            </contact>
            <bounce/>
            <friction>
              <torsional>
                <ode/>
              </torsional>
              <ode/>
            </friction>
          </surface>
        </collision>
        <visual name='chassis_visual'>
          <pose frame=''>0 0 0 0 -0 0</pose>
          <geometry>
            <mesh>
              <scale>0.01 0.01 0.01</scale>
              <uri>/home/kostas/datmo_ws/src/car_demo-master/prius_description/meshes/hybrid_body.obj</uri>
            </mesh>
          </geometry>
        </visual>
        <velocity_decay/>
        <self_collide>0</self_collide>
        <enable_wind>0</enable_wind>
        <kinematic>0</kinematic>
      </link>
      <joint name='base_link_connection' type='revolute'>
        <child>chassis</child>
        <parent>base_link</parent>
        <axis>
          <limit>
            <lower>0</lower>
            <upper>0</upper>
          </limit>
          <dynamics>
            <damping>0</damping>
            <friction>0</friction>
            <spring_reference>0</spring_reference>
            <spring_stiffness>0</spring_stiffness>
          </dynamics>
          <use_parent_model_frame>1</use_parent_model_frame>
          <xyz>0 0 1</xyz>
        </axis>
        <physics>
          <ode>
            <limit>
              <cfm>0</cfm>
              <erp>0.2</erp>
            </limit>
          </ode>
        </physics>
      </joint>
      <link name='fl_axle'>
        <pose frame=''>2.86061 0.765877 0.3 0 -0 1.57</pose>
        <inertial>
          <pose frame=''>0 0 0 0 -0 0</pose>
          <mass>1</mass>
          <inertia>
            <ixx>0.004</ixx>
            <ixy>0</ixy>
            <ixz>0</ixz>
            <iyy>0.004</iyy>
            <iyz>0</iyz>
            <izz>0.004</izz>
          </inertia>
        </inertial>
        <self_collide>0</self_collide>
        <enable_wind>0</enable_wind>
        <kinematic>0</kinematic>
      </link>
      <joint name='front_left_steer_joint' type='revolute'>
        <child>fl_axle</child>
        <parent>chassis</parent>
        <axis>
          <xyz>0 0 1</xyz>
          <limit>
            <lower>-1e+16</lower>
            <upper>1e+16</upper>
          </limit>
          <dynamics>
            <spring_reference>0</spring_reference>
            <spring_stiffness>0</spring_stiffness>
          </dynamics>
          <use_parent_model_frame>1</use_parent_model_frame>
        </axis>
      </joint>
      <link name='front_left_wheel'>
        <pose frame=''>2.86061 0.765877 0.3 0 -0 1.57</pose>
        <inertial>
          <pose frame=''>0 0 0 0 -0 0</pose>
          <mass>11</mass>
          <inertia>
            <ixx>0.586312</ixx>
            <ixy>0</ixy>
            <ixz>0</ixz>
            <iyy>0.335529</iyy>
            <iyz>0</iyz>
            <izz>0.335529</izz>
          </inertia>
        </inertial>
        <collision name='front_left_wheel_collision_collision'>
          <pose frame=''>0 0 0 0 -0 0</pose>
          <geometry>
            <sphere>
              <radius>0.31265</radius>
            </sphere>
          </geometry>
          <surface>
            <contact>
              <ode>
                <kp>1e+08</kp>
                <min_depth>0.005</min_depth>
              </ode>
            </contact>
            <friction>
              <ode>
                <mu>0.9</mu>
                <mu2>0.9</mu2>
              </ode>
              <torsional>
                <ode/>
              </torsional>
            </friction>
            <bounce/>
          </surface>
          <max_contacts>10</max_contacts>
        </collision>
        <visual name='front_left_wheel_visual'>
          <pose frame=''>0 0 0 0 -0 0</pose>
          <geometry>
            <mesh>
              <scale>0.01 0.01 0.01</scale>
              <uri>/home/kostas/datmo_ws/src/car_demo-master/prius_description/meshes/wheel.obj</uri>
            </mesh>
          </geometry>
          <material>
            <script>
              <uri>__default__</uri>
              <name>__default__</name>
            </script>
          </material>
        </visual>
        <gravity>1</gravity>
        <velocity_decay/>
        <self_collide>0</self_collide>
        <enable_wind>0</enable_wind>
        <kinematic>0</kinematic>
      </link>
      <joint name='front_left_wheel_joint' type='revolute'>
        <child>front_left_wheel</child>
        <parent>fl_axle</parent>
        <axis>
          <xyz>0.000796 1 0</xyz>
          <limit>
            <lower>-1e+16</lower>
            <upper>1e+16</upper>
          </limit>
          <dynamics>
            <spring_reference>0</spring_reference>
            <spring_stiffness>0</spring_stiffness>
          </dynamics>
          <use_parent_model_frame>1</use_parent_model_frame>
        </axis>
      </joint>
      <link name='fr_axle'>
        <pose frame=''>2.85939 -0.768123 0.3 0 -0 1.57</pose>
        <inertial>
          <pose frame=''>0 0 0 0 -0 0</pose>
          <mass>1</mass>
          <inertia>
            <ixx>0.004</ixx>
            <ixy>0</ixy>
            <ixz>0</ixz>
            <iyy>0.004</iyy>
            <iyz>0</iyz>
            <izz>0.004</izz>
          </inertia>
        </inertial>
        <self_collide>0</self_collide>
        <enable_wind>0</enable_wind>
        <kinematic>0</kinematic>
      </link>
      <joint name='front_right_steer_joint' type='revolute'>
        <child>fr_axle</child>
        <parent>chassis</parent>
        <axis>
          <xyz>0 0 1</xyz>
          <limit>
            <lower>-1e+16</lower>
            <upper>1e+16</upper>
          </limit>
          <dynamics>
            <spring_reference>0</spring_reference>
            <spring_stiffness>0</spring_stiffness>
          </dynamics>
          <use_parent_model_frame>1</use_parent_model_frame>
        </axis>
      </joint>
      <link name='front_right_wheel'>
        <pose frame=''>2.85939 -0.768123 0.3 0 -0 1.57</pose>
        <inertial>
          <pose frame=''>0 0 0 0 -0 0</pose>
          <mass>11</mass>
          <inertia>
            <ixx>0.586312</ixx>
            <ixy>0</ixy>
            <ixz>0</ixz>
            <iyy>0.335529</iyy>
            <iyz>0</iyz>
            <izz>0.335529</izz>
          </inertia>
        </inertial>
        <collision name='front_right_wheel_collision_collision'>
          <pose frame=''>0 0 0 0 -0 0</pose>
          <geometry>
            <sphere>
              <radius>0.31265</radius>
            </sphere>
          </geometry>
          <surface>
            <contact>
              <ode>
                <kp>1e+08</kp>
                <min_depth>0.005</min_depth>
              </ode>
            </contact>
            <friction>
              <ode>
                <mu>0.9</mu>
                <mu2>0.9</mu2>
              </ode>
              <torsional>
                <ode/>
              </torsional>
            </friction>
            <bounce/>
          </surface>
          <max_contacts>10</max_contacts>
        </collision>
        <visual name='front_right_wheel_visual'>
          <pose frame=''>0 0 0 0 -0 0</pose>
          <geometry>
            <mesh>
              <scale>0.01 0.01 0.01</scale>
              <uri>/home/kostas/datmo_ws/src/car_demo-master/prius_description/meshes/wheel.obj</uri>
            </mesh>
          </geometry>
          <material>
            <script>
              <uri>__default__</uri>
              <name>__default__</name>
            </script>
          </material>
        </visual>
        <gravity>1</gravity>
        <velocity_decay/>
        <self_collide>0</self_collide>
        <enable_wind>0</enable_wind>
        <kinematic>0</kinematic>
      </link>
      <joint name='front_right_wheel_joint' type='revolute'>
        <child>front_right_wheel</child>
        <parent>fr_axle</parent>
        <axis>
          <xyz>0.000796 1 0</xyz>
          <limit>
            <lower>-1e+16</lower>
            <upper>1e+16</upper>
          </limit>
          <dynamics>
            <spring_reference>0</spring_reference>
            <spring_stiffness>0</spring_stiffness>
          </dynamics>
          <use_parent_model_frame>1</use_parent_model_frame>
        </axis>
      </joint>
      <link name='rear_left_wheel'>
        <pose frame=''>0.000632 0.794154 0.3 0 -0 1.57</pose>
        <inertial>
          <pose frame=''>0 0 0 0 -0 0</pose>
          <mass>11</mass>
          <inertia>
            <ixx>0.586312</ixx>
            <ixy>0</ixy>
            <ixz>0</ixz>
            <iyy>0.335529</iyy>
            <iyz>0</iyz>
            <izz>0.335529</izz>
          </inertia>
        </inertial>
        <collision name='rear_left_wheel_collision_collision'>
          <pose frame=''>0 0 0 0 -0 0</pose>
          <geometry>
            <sphere>
              <radius>0.31265</radius>
            </sphere>
          </geometry>
          <surface>
            <contact>
              <ode>
                <kp>1e+08</kp>
                <min_depth>0.005</min_depth>
              </ode>
            </contact>
            <friction>
              <ode>
                <mu>0.9</mu>
                <mu2>0.9</mu2>
              </ode>
              <torsional>
                <ode/>
              </torsional>
            </friction>
            <bounce/>
          </surface>
          <max_contacts>10</max_contacts>
        </collision>
        <visual name='rear_left_wheel_visual'>
          <pose frame=''>0 0 0 0 -0 0</pose>
          <geometry>
            <mesh>
              <scale>0.01 0.01 0.01</scale>
              <uri>/home/kostas/datmo_ws/src/car_demo-master/prius_description/meshes/wheel.obj</uri>
            </mesh>
          </geometry>
          <material>
            <script>
              <uri>__default__</uri>
              <name>__default__</name>
            </script>
          </material>
        </visual>
        <gravity>1</gravity>
        <velocity_decay/>
        <self_collide>0</self_collide>
        <enable_wind>0</enable_wind>
        <kinematic>0</kinematic>
      </link>
      <joint name='rear_left_wheel_joint' type='revolute'>
        <child>rear_left_wheel</child>
        <parent>chassis</parent>
        <axis>
          <xyz>0.000796 1 0</xyz>
          <limit>
            <lower>-1e+16</lower>
            <upper>1e+16</upper>
          </limit>
          <dynamics>
            <spring_reference>0</spring_reference>
            <spring_stiffness>0</spring_stiffness>
          </dynamics>
          <use_parent_model_frame>1</use_parent_model_frame>
        </axis>
      </joint>
      <link name='rear_right_wheel'>
        <pose frame=''>-0.000631 -0.791845 0.3 0 -0 1.57</pose>
        <inertial>
          <pose frame=''>0 0 0 0 -0 0</pose>
          <mass>11</mass>
          <inertia>
            <ixx>0.586312</ixx>
            <ixy>0</ixy>
            <ixz>0</ixz>
            <iyy>0.335529</iyy>
            <iyz>0</iyz>
            <izz>0.335529</izz>
          </inertia>
        </inertial>
        <collision name='rear_right_wheel_collision_collision'>
          <pose frame=''>0 0 0 0 -0 0</pose>
          <geometry>
            <sphere>
              <radius>0.31265</radius>
            </sphere>
          </geometry>
          <surface>
            <contact>
              <ode>
                <kp>1e+08</kp>
                <min_depth>0.005</min_depth>
              </ode>
            </contact>
            <friction>
              <ode>
                <mu>0.9</mu>
                <mu2>0.9</mu2>
              </ode>
              <torsional>
                <ode/>
              </torsional>
            </friction>
            <bounce/>
          </surface>
          <max_contacts>10</max_contacts>
        </collision>
        <visual name='rear_right_wheel_visual'>
          <pose frame=''>0 0 0 0 -0 0</pose>
          <geometry>
            <mesh>
              <scale>0.01 0.01 0.01</scale>
              <uri>/home/kostas/datmo_ws/src/car_demo-master/prius_description/meshes/wheel.obj</uri>
            </mesh>
          </geometry>
          <material>
            <script>
              <uri>__default__</uri>
              <name>__default__</name>
            </script>
          </material>
        </visual>
        <gravity>1</gravity>
        <velocity_decay/>
        <self_collide>0</self_collide>
        <enable_wind>0</enable_wind>
        <kinematic>0</kinematic>
      </link>
      <joint name='rear_right_wheel_joint' type='revolute'>
        <child>rear_right_wheel</child>
        <parent>chassis</parent>
        <axis>
          <xyz>0.000796 1 0</xyz>
          <limit>
            <lower>-1e+16</lower>
            <upper>1e+16</upper>
          </limit>
          <dynamics>
            <spring_reference>0</spring_reference>
            <spring_stiffness>0</spring_stiffness>
          </dynamics>
          <use_parent_model_frame>1</use_parent_model_frame>
        </axis>
      </joint>
      <link name='steering_wheel'>
        <pose frame=''>2.07815 0.357234 0.988243 -1.3021 0 1.57</pose>
        <inertial>
          <pose frame=''>0 0 0 0 -0 0</pose>
          <mass>1</mass>
          <inertia>
            <ixx>0.145833</ixx>
            <ixy>0</ixy>
            <ixz>0</ixz>
            <iyy>0.145833</iyy>
            <iyz>0</iyz>
            <izz>0.125</izz>
          </inertia>
        </inertial>
        <visual name='steering_wheel_visual'>
          <pose frame=''>0 0 0 1.3021 -0 0</pose>
          <geometry>
            <mesh>
              <scale>0.01 0.01 0.01</scale>
              <uri>/home/kostas/datmo_ws/src/car_demo-master/prius_description/meshes/steering_wheel.obj</uri>
            </mesh>
          </geometry>
        </visual>
        <self_collide>0</self_collide>
        <enable_wind>0</enable_wind>
        <kinematic>0</kinematic>
      </link>
      <joint name='steering_joint' type='revolute'>
        <child>steering_wheel</child>
        <parent>chassis</parent>
        <axis>
          <xyz>-0.964118 0.000768 0.265474</xyz>
          <limit>
            <lower>-1e+16</lower>
            <upper>1e+16</upper>
          </limit>
          <dynamics>
            <spring_reference>0</spring_reference>
            <spring_stiffness>0</spring_stiffness>
          </dynamics>
          <use_parent_model_frame>1</use_parent_model_frame>
        </axis>
      </joint>
      <plugin name='actorhybrid_drive' filename='libActor.so'>
	<controlTopic>actor</controlTopic>
        <chassis>chassis</chassis>
        <front_left_wheel>front_left_wheel_joint</front_left_wheel>
        <front_right_wheel>front_right_wheel_joint</front_right_wheel>
        <front_left_wheel_steering>front_left_steer_joint</front_left_wheel_steering>
        <front_right_wheel_steering>front_right_steer_joint</front_right_wheel_steering>
        <back_left_wheel>rear_left_wheel_joint</back_left_wheel>
        <back_right_wheel>rear_right_wheel_joint</back_right_wheel>
        <steering_wheel>steering_joint</steering_wheel>
        <chassis_aero_force_gain>0.63045</chassis_aero_force_gain>
        <front_torque>700.4004393000001</front_torque>
        <back_torque>0</back_torque>
        <front_brake_torque>1031.28052716</front_brake_torque>
        <back_brake_torque>687.5203514400001</back_brake_torque>
        <max_speed>37.998337013956565</max_speed>
        <min_gas_flow>8.981854013171626e-05</min_gas_flow>
        <gas_efficiency>0.371</gas_efficiency>
        <battery_charge_watt_hours>291</battery_charge_watt_hours>
        <battery_discharge_watt_hours>214</battery_discharge_watt_hours>
        <max_steer>0.8458</max_steer>
        <flwheel_steering_p_gain>1e4</flwheel_steering_p_gain>
        <frwheel_steering_p_gain>1e4</frwheel_steering_p_gain>
        <flwheel_steering_i_gain>0</flwheel_steering_i_gain>
        <frwheel_steering_i_gain>0</frwheel_steering_i_gain>
        <flwheel_steering_d_gain>3e2</flwheel_steering_d_gain>
        <frwheel_steering_d_gain>3e2</frwheel_steering_d_gain>
        <robotNamespace>/</robotNamespace>
      </plugin>
      <plugin name='joint_state_publisher' filename='libgazebo_ros_joint_state_publisher.so'>
        <jointName>rear_right_wheel_joint, rear_left_wheel_joint, front_right_wheel_joint, front_left_wheel_joint, front_right_steer_joint, front_left_steer_joint, steering_joint</jointName>
        <updateRate>100.0</updateRate>
        <alwaysOn>1</alwaysOn>
        <robotNamespace>/</robotNamespace>
      </plugin>
      <static>0</static>
      <plugin name='p3d' filename='libgazebo_ros_p3d.so'>
        <bodyName>base_link</bodyName>
        <topicName>robot_1</topicName>
        <frameName>map</frameName>
        <updateRate>100.0</updateRate>
        <robotNamespace>/</robotNamespace>
      </plugin>
      <pose frame=''>-28 -7.4518 0.006903 0 0.000236 0.104877</pose>
    </model>
  </world>
</sdf>
